Internal Server Error: /users/top-up/
Traceback (most recent call last):
  File "C:\Users\krato\AppData\Roaming\Python\Python313\site-packages\django\core\handlers\exception.py", line 55, in inner
    response = get_response(request)
  File "C:\Users\krato\AppData\Roaming\Python\Python313\site-packages\django\core\handlers\base.py", line 197, in _get_response
    response = wrapped_callback(request, *callback_args, **callback_kwargs)
  File "C:\Users\krato\ssa_project\users\views.py", line 90, in top_up
    return render(request, 'users/topup.html', {'form': form, 'balance': Profile.balance})
  File "C:\Users\krato\AppData\Roaming\Python\Python313\site-packages\django\shortcuts.py", line 25, in render
    content = loader.render_to_string(template_name, context, request, using=using)
  File "C:\Users\krato\AppData\Roaming\Python\Python313\site-packages\django\template\loader.py", line 61, in render_to_string
    template = get_template(template_name, using=using)
  File "C:\Users\krato\AppData\Roaming\Python\Python313\site-packages\django\template\loader.py", line 19, in get_template
    raise TemplateDoesNotExist(template_name, chain=chain)
django.template.exceptions.TemplateDoesNotExist: users/topup.html
"GET /users/top-up/ HTTP/1.1" 500 80719
Internal Server Error: /users/top-up/
Traceback (most recent call last):
  File "C:\Users\krato\AppData\Roaming\Python\Python313\site-packages\django\core\handlers\exception.py", line 55, in inner
    response = get_response(request)
  File "C:\Users\krato\AppData\Roaming\Python\Python313\site-packages\django\core\handlers\base.py", line 197, in _get_response
    response = wrapped_callback(request, *callback_args, **callback_kwargs)
  File "C:\Users\krato\ssa_project\users\views.py", line 90, in top_up
    return render(request, 'users/topup.html', {'form': form, 'balance': Profile.balance})
  File "C:\Users\krato\AppData\Roaming\Python\Python313\site-packages\django\shortcuts.py", line 25, in render
    content = loader.render_to_string(template_name, context, request, using=using)
  File "C:\Users\krato\AppData\Roaming\Python\Python313\site-packages\django\template\loader.py", line 61, in render_to_string
    template = get_template(template_name, using=using)
  File "C:\Users\krato\AppData\Roaming\Python\Python313\site-packages\django\template\loader.py", line 19, in get_template
    raise TemplateDoesNotExist(template_name, chain=chain)
django.template.exceptions.TemplateDoesNotExist: users/topup.html
"GET /users/top-up/ HTTP/1.1" 500 80786
Internal Server Error: /chipin/group/5/event/8/transfer_funds/
Traceback (most recent call last):
  File "C:\Users\krato\AppData\Roaming\Python\Python313\site-packages\django\core\handlers\exception.py", line 55, in inner
    response = get_response(request)
  File "C:\Users\krato\AppData\Roaming\Python\Python313\site-packages\django\core\handlers\base.py", line 197, in _get_response
    response = wrapped_callback(request, *callback_args, **callback_kwargs)
  File "C:\Users\krato\ssa_project\chipin\views.py", line 39, in transfer_funds
    if insufficient_funds == True:
       ^^^^^^^^^^^^^^^^^^
UnboundLocalError: cannot access local variable 'insufficient_funds' where it is not associated with a value
"GET /chipin/group/5/event/8/transfer_funds/ HTTP/1.1" 500 65770
Internal Server Error: /chipin/group/5/event/8/transfer_funds/
Traceback (most recent call last):
  File "C:\Users\krato\AppData\Roaming\Python\Python313\site-packages\django\core\handlers\exception.py", line 55, in inner
    response = get_response(request)
  File "C:\Users\krato\AppData\Roaming\Python\Python313\site-packages\django\core\handlers\base.py", line 197, in _get_response
    response = wrapped_callback(request, *callback_args, **callback_kwargs)
  File "C:\Users\krato\ssa_project\chipin\views.py", line 39, in transfer_funds
    if insufficient_funds > 0:
       ^^^^^^^^^^^^^^^^^^
UnboundLocalError: cannot access local variable 'insufficient_funds' where it is not associated with a value
"GET /chipin/group/5/event/8/transfer_funds/ HTTP/1.1" 500 66168
Internal Server Error: /chipin/group/5/event/8/transfer_funds/
Traceback (most recent call last):
  File "C:\Users\krato\AppData\Roaming\Python\Python313\site-packages\django\core\handlers\exception.py", line 55, in inner
    response = get_response(request)
  File "C:\Users\krato\AppData\Roaming\Python\Python313\site-packages\django\core\handlers\base.py", line 197, in _get_response
    response = wrapped_callback(request, *callback_args, **callback_kwargs)
  File "C:\Users\krato\ssa_project\chipin\views.py", line 39, in transfer_funds
    if insufficient_funds > 0:
       ^^^^^^^^^^^^^^^^^^
UnboundLocalError: cannot access local variable 'insufficient_funds' where it is not associated with a value
"GET /chipin/group/5/event/8/transfer_funds/ HTTP/1.1" 500 65768
Internal Server Error: /chipin/group/5/event/8/transfer_funds/
Traceback (most recent call last):
  File "C:\Users\krato\AppData\Roaming\Python\Python313\site-packages\django\core\handlers\exception.py", line 55, in inner
    response = get_response(request)
  File "C:\Users\krato\AppData\Roaming\Python\Python313\site-packages\django\core\handlers\base.py", line 197, in _get_response
    response = wrapped_callback(request, *callback_args, **callback_kwargs)
  File "C:\Users\krato\ssa_project\chipin\views.py", line 39, in transfer_funds
    if insufficient_funds > 0:
       ^^^^^^^^^^^^^^^^^^
UnboundLocalError: cannot access local variable 'insufficient_funds' where it is not associated with a value
"GET /chipin/group/5/event/8/transfer_funds/ HTTP/1.1" 500 66031
Internal Server Error: /chipin/group/5/event/8/transfer_funds/
Traceback (most recent call last):
  File "C:\Users\krato\AppData\Roaming\Python\Python313\site-packages\django\core\handlers\exception.py", line 55, in inner
    response = get_response(request)
  File "C:\Users\krato\AppData\Roaming\Python\Python313\site-packages\django\core\handlers\base.py", line 197, in _get_response
    response = wrapped_callback(request, *callback_args, **callback_kwargs)
  File "C:\Users\krato\ssa_project\chipin\views.py", line 39, in transfer_funds
    if insufficient_funds > 0:
       ^^^^^^^^^^^^^^^^^^
UnboundLocalError: cannot access local variable 'insufficient_funds' where it is not associated with a value
"GET /chipin/group/5/event/8/transfer_funds/ HTTP/1.1" 500 66325
Internal Server Error: /users/register/
Traceback (most recent call last):
  File "C:\Users\krato\AppData\Roaming\Python\Python313\site-packages\django\db\models\query.py", line 948, in get_or_create
    return self.get(**kwargs), False
           ~~~~~~~~^^^^^^^^^^
  File "C:\Users\krato\AppData\Roaming\Python\Python313\site-packages\django\db\models\query.py", line 649, in get
    raise self.model.DoesNotExist(
        "%s matching query does not exist." % self.model._meta.object_name
    )
users.models.Profile.DoesNotExist: Profile matching query does not exist.

During handling of the above exception, another exception occurred:

Traceback (most recent call last):
  File "C:\Users\krato\AppData\Roaming\Python\Python313\site-packages\django\core\handlers\exception.py", line 55, in inner
    response = get_response(request)
  File "C:\Users\krato\AppData\Roaming\Python\Python313\site-packages\django\core\handlers\base.py", line 197, in _get_response
    response = wrapped_callback(request, *callback_args, **callback_kwargs)
  File "C:\Users\krato\ssa_project\users\views.py", line 16, in register
    form.save()
    ~~~~~~~~~^^
  File "C:\Users\krato\ssa_project\users\forms.py", line 24, in save
    user.save()
    ~~~~~~~~~^^
  File "C:\Users\krato\AppData\Roaming\Python\Python313\site-packages\django\contrib\auth\base_user.py", line 62, in save
    super().save(*args, **kwargs)
    ~~~~~~~~~~~~^^^^^^^^^^^^^^^^^
  File "C:\Users\krato\AppData\Roaming\Python\Python313\site-packages\django\db\models\base.py", line 891, in save
    self.save_base(
    ~~~~~~~~~~~~~~^
        using=using,
        ^^^^^^^^^^^^
    ...<2 lines>...
        update_fields=update_fields,
        ^^^^^^^^^^^^^^^^^^^^^^^^^^^^
    )
    ^
  File "C:\Users\krato\AppData\Roaming\Python\Python313\site-packages\django\db\models\base.py", line 1012, in save_base
    post_save.send(
    ~~~~~~~~~~~~~~^
        sender=origin,
        ^^^^^^^^^^^^^^
    ...<4 lines>...
        using=using,
        ^^^^^^^^^^^^
    )
    ^
  File "C:\Users\krato\AppData\Roaming\Python\Python313\site-packages\django\dispatch\dispatcher.py", line 189, in send
    response = receiver(signal=self, sender=sender, **named)
  File "C:\Users\krato\ssa_project\users\models.py", line 10, in create_user_profile
    Profile.objects.get_or_create(user=instance)  # Safely create the profile without duplicating
    ~~~~~~~~~~~~~~~~~~~~~~~~~~~~~^^^^^^^^^^^^^^^
  File "C:\Users\krato\AppData\Roaming\Python\Python313\site-packages\django\db\models\manager.py", line 87, in manager_method
    return getattr(self.get_queryset(), name)(*args, **kwargs)
           ~~~~~~~~~~~~~~~~~~~~~~~~~~~~~~~~~~^^^^^^^^^^^^^^^^^
  File "C:\Users\krato\AppData\Roaming\Python\Python313\site-packages\django\db\models\query.py", line 955, in get_or_create
    return self.create(**params), True
           ~~~~~~~~~~~^^^^^^^^^^
  File "C:\Users\krato\AppData\Roaming\Python\Python313\site-packages\django\db\models\query.py", line 679, in create
    obj.save(force_insert=True, using=self.db)
    ~~~~~~~~^^^^^^^^^^^^^^^^^^^^^^^^^^^^^^^^^^
  File "C:\Users\krato\ssa_project\users\models.py", line 39, in save
    self.clean()
    ~~~~~~~~~~^^
  File "C:\Users\krato\ssa_project\users\models.py", line 36, in clean
    validate_unique_nickname(self.nickname, instance=self)
    ~~~~~~~~~~~~~~~~~~~~~~~~^^^^^^^^^^^^^^^^^^^^^^^^^^^^^^
  File "C:\Users\krato\ssa_project\users\models.py", line 21, in validate_unique_nickname
    raise ValidationError(f"Nickname '{nickname}' is already taken.")
django.core.exceptions.ValidationError: ["Nickname '' is already taken."]
"POST /users/register/ HTTP/1.1" 500 129289
Internal Server Error: /users/register/
Traceback (most recent call last):
  File "C:\Users\krato\AppData\Roaming\Python\Python313\site-packages\django\db\models\query.py", line 948, in get_or_create
    return self.get(**kwargs), False
           ~~~~~~~~^^^^^^^^^^
  File "C:\Users\krato\AppData\Roaming\Python\Python313\site-packages\django\db\models\query.py", line 649, in get
    raise self.model.DoesNotExist(
        "%s matching query does not exist." % self.model._meta.object_name
    )
users.models.Profile.DoesNotExist: Profile matching query does not exist.

During handling of the above exception, another exception occurred:

Traceback (most recent call last):
  File "C:\Users\krato\AppData\Roaming\Python\Python313\site-packages\django\core\handlers\exception.py", line 55, in inner
    response = get_response(request)
  File "C:\Users\krato\AppData\Roaming\Python\Python313\site-packages\django\core\handlers\base.py", line 197, in _get_response
    response = wrapped_callback(request, *callback_args, **callback_kwargs)
  File "C:\Users\krato\ssa_project\users\views.py", line 16, in register
    form.save()
    ~~~~~~~~~^^
  File "C:\Users\krato\ssa_project\users\forms.py", line 24, in save
    user.save()
    ~~~~~~~~~^^
  File "C:\Users\krato\AppData\Roaming\Python\Python313\site-packages\django\contrib\auth\base_user.py", line 62, in save
    super().save(*args, **kwargs)
    ~~~~~~~~~~~~^^^^^^^^^^^^^^^^^
  File "C:\Users\krato\AppData\Roaming\Python\Python313\site-packages\django\db\models\base.py", line 891, in save
    self.save_base(
    ~~~~~~~~~~~~~~^
        using=using,
        ^^^^^^^^^^^^
    ...<2 lines>...
        update_fields=update_fields,
        ^^^^^^^^^^^^^^^^^^^^^^^^^^^^
    )
    ^
  File "C:\Users\krato\AppData\Roaming\Python\Python313\site-packages\django\db\models\base.py", line 1012, in save_base
    post_save.send(
    ~~~~~~~~~~~~~~^
        sender=origin,
        ^^^^^^^^^^^^^^
    ...<4 lines>...
        using=using,
        ^^^^^^^^^^^^
    )
    ^
  File "C:\Users\krato\AppData\Roaming\Python\Python313\site-packages\django\dispatch\dispatcher.py", line 189, in send
    response = receiver(signal=self, sender=sender, **named)
  File "C:\Users\krato\ssa_project\users\models.py", line 10, in create_user_profile
    Profile.objects.get_or_create(user=instance)  # Safely create the profile without duplicating
    ~~~~~~~~~~~~~~~~~~~~~~~~~~~~~^^^^^^^^^^^^^^^
  File "C:\Users\krato\AppData\Roaming\Python\Python313\site-packages\django\db\models\manager.py", line 87, in manager_method
    return getattr(self.get_queryset(), name)(*args, **kwargs)
           ~~~~~~~~~~~~~~~~~~~~~~~~~~~~~~~~~~^^^^^^^^^^^^^^^^^
  File "C:\Users\krato\AppData\Roaming\Python\Python313\site-packages\django\db\models\query.py", line 955, in get_or_create
    return self.create(**params), True
           ~~~~~~~~~~~^^^^^^^^^^
  File "C:\Users\krato\AppData\Roaming\Python\Python313\site-packages\django\db\models\query.py", line 679, in create
    obj.save(force_insert=True, using=self.db)
    ~~~~~~~~^^^^^^^^^^^^^^^^^^^^^^^^^^^^^^^^^^
  File "C:\Users\krato\ssa_project\users\models.py", line 39, in save
    self.clean()
    ~~~~~~~~~~^^
  File "C:\Users\krato\ssa_project\users\models.py", line 36, in clean
    validate_unique_nickname(self.nickname, instance=self)
    ~~~~~~~~~~~~~~~~~~~~~~~~^^^^^^^^^^^^^^^^^^^^^^^^^^^^^^
  File "C:\Users\krato\ssa_project\users\models.py", line 21, in validate_unique_nickname
    raise ValidationError(f"Nickname '{nickname}' is already taken.")
django.core.exceptions.ValidationError: ["Nickname '' is already taken."]
"POST /users/register/ HTTP/1.1" 500 145
Internal Server Error: /users/register/
Traceback (most recent call last):
  File "C:\Users\krato\AppData\Roaming\Python\Python313\site-packages\django\db\models\query.py", line 948, in get_or_create
    return self.get(**kwargs), False
           ~~~~~~~~^^^^^^^^^^
  File "C:\Users\krato\AppData\Roaming\Python\Python313\site-packages\django\db\models\query.py", line 649, in get
    raise self.model.DoesNotExist(
        "%s matching query does not exist." % self.model._meta.object_name
    )
users.models.Profile.DoesNotExist: Profile matching query does not exist.

During handling of the above exception, another exception occurred:

Traceback (most recent call last):
  File "C:\Users\krato\AppData\Roaming\Python\Python313\site-packages\django\core\handlers\exception.py", line 55, in inner
    response = get_response(request)
  File "C:\Users\krato\AppData\Roaming\Python\Python313\site-packages\django\core\handlers\base.py", line 197, in _get_response
    response = wrapped_callback(request, *callback_args, **callback_kwargs)
  File "C:\Users\krato\ssa_project\users\views.py", line 16, in register
    form.save()
    ~~~~~~~~~^^
  File "C:\Users\krato\ssa_project\users\forms.py", line 24, in save
    user.save()
    ~~~~~~~~~^^
  File "C:\Users\krato\AppData\Roaming\Python\Python313\site-packages\django\contrib\auth\base_user.py", line 62, in save
    super().save(*args, **kwargs)
    ~~~~~~~~~~~~^^^^^^^^^^^^^^^^^
  File "C:\Users\krato\AppData\Roaming\Python\Python313\site-packages\django\db\models\base.py", line 891, in save
    self.save_base(
    ~~~~~~~~~~~~~~^
        using=using,
        ^^^^^^^^^^^^
    ...<2 lines>...
        update_fields=update_fields,
        ^^^^^^^^^^^^^^^^^^^^^^^^^^^^
    )
    ^
  File "C:\Users\krato\AppData\Roaming\Python\Python313\site-packages\django\db\models\base.py", line 1012, in save_base
    post_save.send(
    ~~~~~~~~~~~~~~^
        sender=origin,
        ^^^^^^^^^^^^^^
    ...<4 lines>...
        using=using,
        ^^^^^^^^^^^^
    )
    ^
  File "C:\Users\krato\AppData\Roaming\Python\Python313\site-packages\django\dispatch\dispatcher.py", line 189, in send
    response = receiver(signal=self, sender=sender, **named)
  File "C:\Users\krato\ssa_project\users\models.py", line 10, in create_user_profile
    Profile.objects.get_or_create(user=instance)  # Safely create the profile without duplicating
    ~~~~~~~~~~~~~~~~~~~~~~~~~~~~~^^^^^^^^^^^^^^^
  File "C:\Users\krato\AppData\Roaming\Python\Python313\site-packages\django\db\models\manager.py", line 87, in manager_method
    return getattr(self.get_queryset(), name)(*args, **kwargs)
           ~~~~~~~~~~~~~~~~~~~~~~~~~~~~~~~~~~^^^^^^^^^^^^^^^^^
  File "C:\Users\krato\AppData\Roaming\Python\Python313\site-packages\django\db\models\query.py", line 955, in get_or_create
    return self.create(**params), True
           ~~~~~~~~~~~^^^^^^^^^^
  File "C:\Users\krato\AppData\Roaming\Python\Python313\site-packages\django\db\models\query.py", line 679, in create
    obj.save(force_insert=True, using=self.db)
    ~~~~~~~~^^^^^^^^^^^^^^^^^^^^^^^^^^^^^^^^^^
  File "C:\Users\krato\ssa_project\users\models.py", line 39, in save
    self.clean()
    ~~~~~~~~~~^^
  File "C:\Users\krato\ssa_project\users\models.py", line 36, in clean
    validate_unique_nickname(self.nickname, instance=self)
    ~~~~~~~~~~~~~~~~~~~~~~~~^^^^^^^^^^^^^^^^^^^^^^^^^^^^^^
  File "C:\Users\krato\ssa_project\users\models.py", line 21, in validate_unique_nickname
    raise ValidationError(f"Nickname '{nickname}' is already taken.")
django.core.exceptions.ValidationError: ["Nickname '' is already taken."]
"POST /users/register/ HTTP/1.1" 500 129198
Internal Server Error: /users/
Traceback (most recent call last):
  File "C:\Users\krato\AppData\Roaming\Python\Python313\site-packages\django\core\handlers\exception.py", line 55, in inner
    response = get_response(request)
  File "C:\Users\krato\AppData\Roaming\Python\Python313\site-packages\django\core\handlers\base.py", line 197, in _get_response
    response = wrapped_callback(request, *callback_args, **callback_kwargs)
  File "C:\Users\krato\AppData\Roaming\Python\Python313\site-packages\django\contrib\auth\decorators.py", line 60, in _view_wrapper
    return view_func(request, *args, **kwargs)
  File "C:\Users\krato\ssa_project\users\views.py", line 94, in user
    profile = request.user.profile
              ^^^^^^^^^^^^^^^^^^^^
  File "C:\Users\krato\AppData\Roaming\Python\Python313\site-packages\django\utils\functional.py", line 253, in inner
    return func(_wrapped, *args)
  File "C:\Users\krato\AppData\Roaming\Python\Python313\site-packages\django\db\models\fields\related_descriptors.py", line 531, in __get__
    raise self.RelatedObjectDoesNotExist(
    ...<2 lines>...
    )
django.contrib.auth.models.User.profile.RelatedObjectDoesNotExist: User has no profile.
"GET /users/ HTTP/1.1" 500 78302
Internal Server Error: /users/register/
Traceback (most recent call last):
  File "C:\Users\krato\AppData\Roaming\Python\Python313\site-packages\django\db\models\query.py", line 948, in get_or_create
    return self.get(**kwargs), False
           ~~~~~~~~^^^^^^^^^^
  File "C:\Users\krato\AppData\Roaming\Python\Python313\site-packages\django\db\models\query.py", line 649, in get
    raise self.model.DoesNotExist(
        "%s matching query does not exist." % self.model._meta.object_name
    )
users.models.Profile.DoesNotExist: Profile matching query does not exist.

During handling of the above exception, another exception occurred:

Traceback (most recent call last):
  File "C:\Users\krato\AppData\Roaming\Python\Python313\site-packages\django\core\handlers\exception.py", line 55, in inner
    response = get_response(request)
  File "C:\Users\krato\AppData\Roaming\Python\Python313\site-packages\django\core\handlers\base.py", line 197, in _get_response
    response = wrapped_callback(request, *callback_args, **callback_kwargs)
  File "C:\Users\krato\ssa_project\users\views.py", line 16, in register
    form.save()
    ~~~~~~~~~^^
  File "C:\Users\krato\ssa_project\users\forms.py", line 24, in save
    user.save()
    ~~~~~~~~~^^
  File "C:\Users\krato\AppData\Roaming\Python\Python313\site-packages\django\contrib\auth\base_user.py", line 62, in save
    super().save(*args, **kwargs)
    ~~~~~~~~~~~~^^^^^^^^^^^^^^^^^
  File "C:\Users\krato\AppData\Roaming\Python\Python313\site-packages\django\db\models\base.py", line 891, in save
    self.save_base(
    ~~~~~~~~~~~~~~^
        using=using,
        ^^^^^^^^^^^^
    ...<2 lines>...
        update_fields=update_fields,
        ^^^^^^^^^^^^^^^^^^^^^^^^^^^^
    )
    ^
  File "C:\Users\krato\AppData\Roaming\Python\Python313\site-packages\django\db\models\base.py", line 1012, in save_base
    post_save.send(
    ~~~~~~~~~~~~~~^
        sender=origin,
        ^^^^^^^^^^^^^^
    ...<4 lines>...
        using=using,
        ^^^^^^^^^^^^
    )
    ^
  File "C:\Users\krato\AppData\Roaming\Python\Python313\site-packages\django\dispatch\dispatcher.py", line 189, in send
    response = receiver(signal=self, sender=sender, **named)
  File "C:\Users\krato\ssa_project\users\models.py", line 11, in create_user_profile
    Profile.objects.get_or_create(user=instance)  # Safely create the profile without duplicating
    ~~~~~~~~~~~~~~~~~~~~~~~~~~~~~^^^^^^^^^^^^^^^
  File "C:\Users\krato\AppData\Roaming\Python\Python313\site-packages\django\db\models\manager.py", line 87, in manager_method
    return getattr(self.get_queryset(), name)(*args, **kwargs)
           ~~~~~~~~~~~~~~~~~~~~~~~~~~~~~~~~~~^^^^^^^^^^^^^^^^^
  File "C:\Users\krato\AppData\Roaming\Python\Python313\site-packages\django\db\models\query.py", line 955, in get_or_create
    return self.create(**params), True
           ~~~~~~~~~~~^^^^^^^^^^
  File "C:\Users\krato\AppData\Roaming\Python\Python313\site-packages\django\db\models\query.py", line 679, in create
    obj.save(force_insert=True, using=self.db)
    ~~~~~~~~^^^^^^^^^^^^^^^^^^^^^^^^^^^^^^^^^^
  File "C:\Users\krato\ssa_project\users\models.py", line 44, in save
    self.clean()  # Ensure the clean method is called
    ~~~~~~~~~~^^
  File "C:\Users\krato\ssa_project\users\models.py", line 40, in clean
    raise ValidationError("Nickname cannot be empty.")
django.core.exceptions.ValidationError: ['Nickname cannot be empty.']
"POST /users/register/ HTTP/1.1" 500 125069
Internal Server Error: /users/register/
Traceback (most recent call last):
  File "C:\Users\krato\AppData\Roaming\Python\Python313\site-packages\django\db\models\query.py", line 948, in get_or_create
    return self.get(**kwargs), False
           ~~~~~~~~^^^^^^^^^^
  File "C:\Users\krato\AppData\Roaming\Python\Python313\site-packages\django\db\models\query.py", line 649, in get
    raise self.model.DoesNotExist(
        "%s matching query does not exist." % self.model._meta.object_name
    )
users.models.Profile.DoesNotExist: Profile matching query does not exist.

During handling of the above exception, another exception occurred:

Traceback (most recent call last):
  File "C:\Users\krato\AppData\Roaming\Python\Python313\site-packages\django\core\handlers\exception.py", line 55, in inner
    response = get_response(request)
  File "C:\Users\krato\AppData\Roaming\Python\Python313\site-packages\django\core\handlers\base.py", line 197, in _get_response
    response = wrapped_callback(request, *callback_args, **callback_kwargs)
  File "C:\Users\krato\ssa_project\users\views.py", line 16, in register
    form.save()
    ~~~~~~~~~^^
  File "C:\Users\krato\ssa_project\users\forms.py", line 24, in save
    user.save()
    ~~~~~~~~~^^
  File "C:\Users\krato\AppData\Roaming\Python\Python313\site-packages\django\contrib\auth\base_user.py", line 62, in save
    super().save(*args, **kwargs)
    ~~~~~~~~~~~~^^^^^^^^^^^^^^^^^
  File "C:\Users\krato\AppData\Roaming\Python\Python313\site-packages\django\db\models\base.py", line 891, in save
    self.save_base(
    ~~~~~~~~~~~~~~^
        using=using,
        ^^^^^^^^^^^^
    ...<2 lines>...
        update_fields=update_fields,
        ^^^^^^^^^^^^^^^^^^^^^^^^^^^^
    )
    ^
  File "C:\Users\krato\AppData\Roaming\Python\Python313\site-packages\django\db\models\base.py", line 1012, in save_base
    post_save.send(
    ~~~~~~~~~~~~~~^
        sender=origin,
        ^^^^^^^^^^^^^^
    ...<4 lines>...
        using=using,
        ^^^^^^^^^^^^
    )
    ^
  File "C:\Users\krato\AppData\Roaming\Python\Python313\site-packages\django\dispatch\dispatcher.py", line 189, in send
    response = receiver(signal=self, sender=sender, **named)
  File "C:\Users\krato\ssa_project\users\models.py", line 11, in create_user_profile
    Profile.objects.get_or_create(user=instance)  # Safely create the profile without duplicating
    ~~~~~~~~~~~~~~~~~~~~~~~~~~~~~^^^^^^^^^^^^^^^
  File "C:\Users\krato\AppData\Roaming\Python\Python313\site-packages\django\db\models\manager.py", line 87, in manager_method
    return getattr(self.get_queryset(), name)(*args, **kwargs)
           ~~~~~~~~~~~~~~~~~~~~~~~~~~~~~~~~~~^^^^^^^^^^^^^^^^^
  File "C:\Users\krato\AppData\Roaming\Python\Python313\site-packages\django\db\models\query.py", line 955, in get_or_create
    return self.create(**params), True
           ~~~~~~~~~~~^^^^^^^^^^
  File "C:\Users\krato\AppData\Roaming\Python\Python313\site-packages\django\db\models\query.py", line 679, in create
    obj.save(force_insert=True, using=self.db)
    ~~~~~~~~^^^^^^^^^^^^^^^^^^^^^^^^^^^^^^^^^^
  File "C:\Users\krato\ssa_project\users\models.py", line 44, in save
    self.clean()  # Ensure the clean method is called
    ~~~~~~~~~~^^
  File "C:\Users\krato\ssa_project\users\models.py", line 40, in clean
    raise ValidationError("Please enter a nickname.")
django.core.exceptions.ValidationError: ['Please enter a nickname.']
"POST /users/register/ HTTP/1.1" 500 125060
Internal Server Error: /users/register/
Traceback (most recent call last):
  File "C:\Users\krato\AppData\Roaming\Python\Python313\site-packages\django\db\models\query.py", line 948, in get_or_create
    return self.get(**kwargs), False
           ~~~~~~~~^^^^^^^^^^
  File "C:\Users\krato\AppData\Roaming\Python\Python313\site-packages\django\db\models\query.py", line 649, in get
    raise self.model.DoesNotExist(
        "%s matching query does not exist." % self.model._meta.object_name
    )
users.models.Profile.DoesNotExist: Profile matching query does not exist.

During handling of the above exception, another exception occurred:

Traceback (most recent call last):
  File "C:\Users\krato\AppData\Roaming\Python\Python313\site-packages\django\core\handlers\exception.py", line 55, in inner
    response = get_response(request)
  File "C:\Users\krato\AppData\Roaming\Python\Python313\site-packages\django\core\handlers\base.py", line 197, in _get_response
    response = wrapped_callback(request, *callback_args, **callback_kwargs)
  File "C:\Users\krato\ssa_project\users\views.py", line 16, in register
    form.save()
    ~~~~~~~~~^^
  File "C:\Users\krato\ssa_project\users\forms.py", line 24, in save
    user.save()
    ~~~~~~~~~^^
  File "C:\Users\krato\AppData\Roaming\Python\Python313\site-packages\django\contrib\auth\base_user.py", line 62, in save
    super().save(*args, **kwargs)
    ~~~~~~~~~~~~^^^^^^^^^^^^^^^^^
  File "C:\Users\krato\AppData\Roaming\Python\Python313\site-packages\django\db\models\base.py", line 891, in save
    self.save_base(
    ~~~~~~~~~~~~~~^
        using=using,
        ^^^^^^^^^^^^
    ...<2 lines>...
        update_fields=update_fields,
        ^^^^^^^^^^^^^^^^^^^^^^^^^^^^
    )
    ^
  File "C:\Users\krato\AppData\Roaming\Python\Python313\site-packages\django\db\models\base.py", line 1012, in save_base
    post_save.send(
    ~~~~~~~~~~~~~~^
        sender=origin,
        ^^^^^^^^^^^^^^
    ...<4 lines>...
        using=using,
        ^^^^^^^^^^^^
    )
    ^
  File "C:\Users\krato\AppData\Roaming\Python\Python313\site-packages\django\dispatch\dispatcher.py", line 189, in send
    response = receiver(signal=self, sender=sender, **named)
  File "C:\Users\krato\ssa_project\users\models.py", line 10, in create_user_profile
    Profile.objects.get_or_create(user=instance)  # Safely create the profile without duplicating
    ~~~~~~~~~~~~~~~~~~~~~~~~~~~~~^^^^^^^^^^^^^^^
  File "C:\Users\krato\AppData\Roaming\Python\Python313\site-packages\django\db\models\manager.py", line 87, in manager_method
    return getattr(self.get_queryset(), name)(*args, **kwargs)
           ~~~~~~~~~~~~~~~~~~~~~~~~~~~~~~~~~~^^^^^^^^^^^^^^^^^
  File "C:\Users\krato\AppData\Roaming\Python\Python313\site-packages\django\db\models\query.py", line 955, in get_or_create
    return self.create(**params), True
           ~~~~~~~~~~~^^^^^^^^^^
  File "C:\Users\krato\AppData\Roaming\Python\Python313\site-packages\django\db\models\query.py", line 679, in create
    obj.save(force_insert=True, using=self.db)
    ~~~~~~~~^^^^^^^^^^^^^^^^^^^^^^^^^^^^^^^^^^
  File "C:\Users\krato\ssa_project\users\models.py", line 39, in save
    self.clean()
    ~~~~~~~~~~^^
  File "C:\Users\krato\ssa_project\users\models.py", line 36, in clean
    validate_unique_nickname(self.nickname, instance=self)
    ~~~~~~~~~~~~~~~~~~~~~~~~^^^^^^^^^^^^^^^^^^^^^^^^^^^^^^
  File "C:\Users\krato\ssa_project\users\models.py", line 21, in validate_unique_nickname
    raise ValidationError(f"Nickname '{nickname}' is already taken.")
django.core.exceptions.ValidationError: ["Nickname '' is already taken."]
"POST /users/register/ HTTP/1.1" 500 129149
Internal Server Error: /users/register/
Traceback (most recent call last):
  File "C:\Users\krato\AppData\Roaming\Python\Python313\site-packages\django\db\models\query.py", line 948, in get_or_create
    return self.get(**kwargs), False
           ~~~~~~~~^^^^^^^^^^
  File "C:\Users\krato\AppData\Roaming\Python\Python313\site-packages\django\db\models\query.py", line 649, in get
    raise self.model.DoesNotExist(
        "%s matching query does not exist." % self.model._meta.object_name
    )
users.models.Profile.DoesNotExist: Profile matching query does not exist.

During handling of the above exception, another exception occurred:

Traceback (most recent call last):
  File "C:\Users\krato\AppData\Roaming\Python\Python313\site-packages\django\core\handlers\exception.py", line 55, in inner
    response = get_response(request)
  File "C:\Users\krato\AppData\Roaming\Python\Python313\site-packages\django\core\handlers\base.py", line 197, in _get_response
    response = wrapped_callback(request, *callback_args, **callback_kwargs)
  File "C:\Users\krato\ssa_project\users\views.py", line 16, in register
    form.save()
    ~~~~~~~~~^^
  File "C:\Users\krato\ssa_project\users\forms.py", line 24, in save
    user.save()
    ~~~~~~~~~^^
  File "C:\Users\krato\AppData\Roaming\Python\Python313\site-packages\django\contrib\auth\base_user.py", line 62, in save
    super().save(*args, **kwargs)
    ~~~~~~~~~~~~^^^^^^^^^^^^^^^^^
  File "C:\Users\krato\AppData\Roaming\Python\Python313\site-packages\django\db\models\base.py", line 891, in save
    self.save_base(
    ~~~~~~~~~~~~~~^
        using=using,
        ^^^^^^^^^^^^
    ...<2 lines>...
        update_fields=update_fields,
        ^^^^^^^^^^^^^^^^^^^^^^^^^^^^
    )
    ^
  File "C:\Users\krato\AppData\Roaming\Python\Python313\site-packages\django\db\models\base.py", line 1012, in save_base
    post_save.send(
    ~~~~~~~~~~~~~~^
        sender=origin,
        ^^^^^^^^^^^^^^
    ...<4 lines>...
        using=using,
        ^^^^^^^^^^^^
    )
    ^
  File "C:\Users\krato\AppData\Roaming\Python\Python313\site-packages\django\dispatch\dispatcher.py", line 189, in send
    response = receiver(signal=self, sender=sender, **named)
  File "C:\Users\krato\ssa_project\users\models.py", line 12, in create_user_profile
    Profile.objects.get_or_create(user=instance)  # Safely create the profile without duplicating
    ~~~~~~~~~~~~~~~~~~~~~~~~~~~~~^^^^^^^^^^^^^^^
  File "C:\Users\krato\AppData\Roaming\Python\Python313\site-packages\django\db\models\manager.py", line 87, in manager_method
    return getattr(self.get_queryset(), name)(*args, **kwargs)
           ~~~~~~~~~~~~~~~~~~~~~~~~~~~~~~~~~~^^^^^^^^^^^^^^^^^
  File "C:\Users\krato\AppData\Roaming\Python\Python313\site-packages\django\db\models\query.py", line 955, in get_or_create
    return self.create(**params), True
           ~~~~~~~~~~~^^^^^^^^^^
  File "C:\Users\krato\AppData\Roaming\Python\Python313\site-packages\django\db\models\query.py", line 679, in create
    obj.save(force_insert=True, using=self.db)
    ~~~~~~~~^^^^^^^^^^^^^^^^^^^^^^^^^^^^^^^^^^
  File "C:\Users\krato\ssa_project\users\models.py", line 41, in save
    self.clean()
    ~~~~~~~~~~^^
  File "C:\Users\krato\ssa_project\users\models.py", line 38, in clean
    validate_unique_nickname(self.nickname, instance=self)
    ~~~~~~~~~~~~~~~~~~~~~~~~^^^^^^^^^^^^^^^^^^^^^^^^^^^^^^
  File "C:\Users\krato\ssa_project\users\models.py", line 23, in validate_unique_nickname
    raise ValidationError(f"Nickname '{nickname}' is already taken.")
django.core.exceptions.ValidationError: ["Nickname '' is already taken."]
"POST /users/register/ HTTP/1.1" 500 129053
Internal Server Error: /users/register/
Traceback (most recent call last):
  File "C:\Users\krato\AppData\Roaming\Python\Python313\site-packages\django\db\models\query.py", line 948, in get_or_create
    return self.get(**kwargs), False
           ~~~~~~~~^^^^^^^^^^
  File "C:\Users\krato\AppData\Roaming\Python\Python313\site-packages\django\db\models\query.py", line 649, in get
    raise self.model.DoesNotExist(
        "%s matching query does not exist." % self.model._meta.object_name
    )
users.models.Profile.DoesNotExist: Profile matching query does not exist.

During handling of the above exception, another exception occurred:

Traceback (most recent call last):
  File "C:\Users\krato\AppData\Roaming\Python\Python313\site-packages\django\core\handlers\exception.py", line 55, in inner
    response = get_response(request)
  File "C:\Users\krato\AppData\Roaming\Python\Python313\site-packages\django\core\handlers\base.py", line 197, in _get_response
    response = wrapped_callback(request, *callback_args, **callback_kwargs)
  File "C:\Users\krato\ssa_project\users\views.py", line 16, in register
    form.save()
    ~~~~~~~~~^^
  File "C:\Users\krato\ssa_project\users\forms.py", line 24, in save
    user.save()
    ~~~~~~~~~^^
  File "C:\Users\krato\AppData\Roaming\Python\Python313\site-packages\django\contrib\auth\base_user.py", line 62, in save
    super().save(*args, **kwargs)
    ~~~~~~~~~~~~^^^^^^^^^^^^^^^^^
  File "C:\Users\krato\AppData\Roaming\Python\Python313\site-packages\django\db\models\base.py", line 891, in save
    self.save_base(
    ~~~~~~~~~~~~~~^
        using=using,
        ^^^^^^^^^^^^
    ...<2 lines>...
        update_fields=update_fields,
        ^^^^^^^^^^^^^^^^^^^^^^^^^^^^
    )
    ^
  File "C:\Users\krato\AppData\Roaming\Python\Python313\site-packages\django\db\models\base.py", line 1012, in save_base
    post_save.send(
    ~~~~~~~~~~~~~~^
        sender=origin,
        ^^^^^^^^^^^^^^
    ...<4 lines>...
        using=using,
        ^^^^^^^^^^^^
    )
    ^
  File "C:\Users\krato\AppData\Roaming\Python\Python313\site-packages\django\dispatch\dispatcher.py", line 189, in send
    response = receiver(signal=self, sender=sender, **named)
  File "C:\Users\krato\ssa_project\users\models.py", line 12, in create_user_profile
    Profile.objects.get_or_create(user=instance)  # Safely create the profile without duplicating
    ~~~~~~~~~~~~~~~~~~~~~~~~~~~~~^^^^^^^^^^^^^^^
  File "C:\Users\krato\AppData\Roaming\Python\Python313\site-packages\django\db\models\manager.py", line 87, in manager_method
    return getattr(self.get_queryset(), name)(*args, **kwargs)
           ~~~~~~~~~~~~~~~~~~~~~~~~~~~~~~~~~~^^^^^^^^^^^^^^^^^
  File "C:\Users\krato\AppData\Roaming\Python\Python313\site-packages\django\db\models\query.py", line 955, in get_or_create
    return self.create(**params), True
           ~~~~~~~~~~~^^^^^^^^^^
  File "C:\Users\krato\AppData\Roaming\Python\Python313\site-packages\django\db\models\query.py", line 679, in create
    obj.save(force_insert=True, using=self.db)
    ~~~~~~~~^^^^^^^^^^^^^^^^^^^^^^^^^^^^^^^^^^
  File "C:\Users\krato\ssa_project\users\models.py", line 41, in save
    self.clean()
    ~~~~~~~~~~^^
  File "C:\Users\krato\ssa_project\users\models.py", line 38, in clean
    validate_unique_nickname(self.nickname, instance=self)
    ~~~~~~~~~~~~~~~~~~~~~~~~^^^^^^^^^^^^^^^^^^^^^^^^^^^^^^
  File "C:\Users\krato\ssa_project\users\models.py", line 23, in validate_unique_nickname
    raise ValidationError(f"Nickname'{nickname}' is already taken.")
django.core.exceptions.ValidationError: ["Nickname'' is already taken."]
"POST /users/register/ HTTP/1.1" 500 129038
Internal Server Error: /users/register/
Traceback (most recent call last):
  File "C:\Users\krato\AppData\Roaming\Python\Python313\site-packages\django\db\models\query.py", line 948, in get_or_create
    return self.get(**kwargs), False
           ~~~~~~~~^^^^^^^^^^
  File "C:\Users\krato\AppData\Roaming\Python\Python313\site-packages\django\db\models\query.py", line 649, in get
    raise self.model.DoesNotExist(
        "%s matching query does not exist." % self.model._meta.object_name
    )
users.models.Profile.DoesNotExist: Profile matching query does not exist.

During handling of the above exception, another exception occurred:

Traceback (most recent call last):
  File "C:\Users\krato\AppData\Roaming\Python\Python313\site-packages\django\core\handlers\exception.py", line 55, in inner
    response = get_response(request)
  File "C:\Users\krato\AppData\Roaming\Python\Python313\site-packages\django\core\handlers\base.py", line 197, in _get_response
    response = wrapped_callback(request, *callback_args, **callback_kwargs)
  File "C:\Users\krato\ssa_project\users\views.py", line 16, in register
    form.save()
    ~~~~~~~~~^^
  File "C:\Users\krato\ssa_project\users\forms.py", line 24, in save
    user.save()
    ~~~~~~~~~^^
  File "C:\Users\krato\AppData\Roaming\Python\Python313\site-packages\django\contrib\auth\base_user.py", line 62, in save
    super().save(*args, **kwargs)
    ~~~~~~~~~~~~^^^^^^^^^^^^^^^^^
  File "C:\Users\krato\AppData\Roaming\Python\Python313\site-packages\django\db\models\base.py", line 891, in save
    self.save_base(
    ~~~~~~~~~~~~~~^
        using=using,
        ^^^^^^^^^^^^
    ...<2 lines>...
        update_fields=update_fields,
        ^^^^^^^^^^^^^^^^^^^^^^^^^^^^
    )
    ^
  File "C:\Users\krato\AppData\Roaming\Python\Python313\site-packages\django\db\models\base.py", line 1012, in save_base
    post_save.send(
    ~~~~~~~~~~~~~~^
        sender=origin,
        ^^^^^^^^^^^^^^
    ...<4 lines>...
        using=using,
        ^^^^^^^^^^^^
    )
    ^
  File "C:\Users\krato\AppData\Roaming\Python\Python313\site-packages\django\dispatch\dispatcher.py", line 189, in send
    response = receiver(signal=self, sender=sender, **named)
  File "C:\Users\krato\ssa_project\users\models.py", line 11, in create_user_profile
    Profile.objects.get_or_create(user=instance)
    ~~~~~~~~~~~~~~~~~~~~~~~~~~~~~^^^^^^^^^^^^^^^
  File "C:\Users\krato\AppData\Roaming\Python\Python313\site-packages\django\db\models\manager.py", line 87, in manager_method
    return getattr(self.get_queryset(), name)(*args, **kwargs)
           ~~~~~~~~~~~~~~~~~~~~~~~~~~~~~~~~~~^^^^^^^^^^^^^^^^^
  File "C:\Users\krato\AppData\Roaming\Python\Python313\site-packages\django\db\models\query.py", line 955, in get_or_create
    return self.create(**params), True
           ~~~~~~~~~~~^^^^^^^^^^
  File "C:\Users\krato\AppData\Roaming\Python\Python313\site-packages\django\db\models\query.py", line 679, in create
    obj.save(force_insert=True, using=self.db)
    ~~~~~~~~^^^^^^^^^^^^^^^^^^^^^^^^^^^^^^^^^^
  File "C:\Users\krato\ssa_project\users\models.py", line 54, in save
    self.full_clean()  # Ensures clean() is called before saving
    ~~~~~~~~~~~~~~~^^
  File "C:\Users\krato\AppData\Roaming\Python\Python313\site-packages\django\db\models\base.py", line 1650, in full_clean
    raise ValidationError(errors)
django.core.exceptions.ValidationError: {'nickname': ['This field cannot be blank.'], '__all__': ['Nickname cannot be empty.']}
"POST /users/register/ HTTP/1.1" 500 126123
Internal Server Error: /users/register/
Traceback (most recent call last):
  File "C:\Users\krato\AppData\Roaming\Python\Python313\site-packages\django\db\models\query.py", line 948, in get_or_create
    return self.get(**kwargs), False
           ~~~~~~~~^^^^^^^^^^
  File "C:\Users\krato\AppData\Roaming\Python\Python313\site-packages\django\db\models\query.py", line 649, in get
    raise self.model.DoesNotExist(
        "%s matching query does not exist." % self.model._meta.object_name
    )
users.models.Profile.DoesNotExist: Profile matching query does not exist.

During handling of the above exception, another exception occurred:

Traceback (most recent call last):
  File "C:\Users\krato\AppData\Roaming\Python\Python313\site-packages\django\core\handlers\exception.py", line 55, in inner
    response = get_response(request)
  File "C:\Users\krato\AppData\Roaming\Python\Python313\site-packages\django\core\handlers\base.py", line 197, in _get_response
    response = wrapped_callback(request, *callback_args, **callback_kwargs)
  File "C:\Users\krato\ssa_project\users\views.py", line 16, in register
    form.save()
    ~~~~~~~~~^^
  File "C:\Users\krato\ssa_project\users\forms.py", line 24, in save
    user.save()
    ~~~~~~~~~^^
  File "C:\Users\krato\AppData\Roaming\Python\Python313\site-packages\django\contrib\auth\base_user.py", line 62, in save
    super().save(*args, **kwargs)
    ~~~~~~~~~~~~^^^^^^^^^^^^^^^^^
  File "C:\Users\krato\AppData\Roaming\Python\Python313\site-packages\django\db\models\base.py", line 891, in save
    self.save_base(
    ~~~~~~~~~~~~~~^
        using=using,
        ^^^^^^^^^^^^
    ...<2 lines>...
        update_fields=update_fields,
        ^^^^^^^^^^^^^^^^^^^^^^^^^^^^
    )
    ^
  File "C:\Users\krato\AppData\Roaming\Python\Python313\site-packages\django\db\models\base.py", line 1012, in save_base
    post_save.send(
    ~~~~~~~~~~~~~~^
        sender=origin,
        ^^^^^^^^^^^^^^
    ...<4 lines>...
        using=using,
        ^^^^^^^^^^^^
    )
    ^
  File "C:\Users\krato\AppData\Roaming\Python\Python313\site-packages\django\dispatch\dispatcher.py", line 189, in send
    response = receiver(signal=self, sender=sender, **named)
  File "C:\Users\krato\ssa_project\users\models.py", line 33, in create_user_profile
    Profile.objects.get_or_create(user=instance)  # Safely create the profile without duplicating
    ~~~~~~~~~~~~~~~~~~~~~~~~~~~~~^^^^^^^^^^^^^^^
  File "C:\Users\krato\AppData\Roaming\Python\Python313\site-packages\django\db\models\manager.py", line 87, in manager_method
    return getattr(self.get_queryset(), name)(*args, **kwargs)
           ~~~~~~~~~~~~~~~~~~~~~~~~~~~~~~~~~~^^^^^^^^^^^^^^^^^
  File "C:\Users\krato\AppData\Roaming\Python\Python313\site-packages\django\db\models\query.py", line 955, in get_or_create
    return self.create(**params), True
           ~~~~~~~~~~~^^^^^^^^^^
  File "C:\Users\krato\AppData\Roaming\Python\Python313\site-packages\django\db\models\query.py", line 679, in create
    obj.save(force_insert=True, using=self.db)
    ~~~~~~~~^^^^^^^^^^^^^^^^^^^^^^^^^^^^^^^^^^
  File "C:\Users\krato\ssa_project\users\models.py", line 19, in save
    self.clean()
    ~~~~~~~~~~^^
  File "C:\Users\krato\ssa_project\users\models.py", line 16, in clean
    validate_unique_nickname(self.nickname, instance=self)
    ~~~~~~~~~~~~~~~~~~~~~~~~^^^^^^^^^^^^^^^^^^^^^^^^^^^^^^
  File "C:\Users\krato\ssa_project\users\models.py", line 44, in validate_unique_nickname
    raise ValidationError(f"Nickname '{nickname}' is already taken.")
django.core.exceptions.ValidationError: ["Nickname '' is already taken."]
"POST /users/register/ HTTP/1.1" 500 128947
Internal Server Error: /admin/auth/user/add/
Traceback (most recent call last):
  File "C:\Users\krato\AppData\Roaming\Python\Python313\site-packages\django\db\models\query.py", line 948, in get_or_create
    return self.get(**kwargs), False
           ~~~~~~~~^^^^^^^^^^
  File "C:\Users\krato\AppData\Roaming\Python\Python313\site-packages\django\db\models\query.py", line 649, in get
    raise self.model.DoesNotExist(
        "%s matching query does not exist." % self.model._meta.object_name
    )
users.models.Profile.DoesNotExist: Profile matching query does not exist.

During handling of the above exception, another exception occurred:

Traceback (most recent call last):
  File "C:\Users\krato\AppData\Roaming\Python\Python313\site-packages\django\core\handlers\exception.py", line 55, in inner
    response = get_response(request)
  File "C:\Users\krato\AppData\Roaming\Python\Python313\site-packages\django\core\handlers\base.py", line 197, in _get_response
    response = wrapped_callback(request, *callback_args, **callback_kwargs)
  File "C:\Users\krato\AppData\Roaming\Python\Python313\site-packages\django\contrib\admin\options.py", line 718, in wrapper
    return self.admin_site.admin_view(view)(*args, **kwargs)
           ~~~~~~~~~~~~~~~~~~~~~~~~~~~~~~~~^^^^^^^^^^^^^^^^^
  File "C:\Users\krato\AppData\Roaming\Python\Python313\site-packages\django\utils\decorators.py", line 188, in _view_wrapper
    result = _process_exception(request, e)
  File "C:\Users\krato\AppData\Roaming\Python\Python313\site-packages\django\utils\decorators.py", line 186, in _view_wrapper
    response = view_func(request, *args, **kwargs)
  File "C:\Users\krato\AppData\Roaming\Python\Python313\site-packages\django\views\decorators\cache.py", line 80, in _view_wrapper
    response = view_func(request, *args, **kwargs)
  File "C:\Users\krato\AppData\Roaming\Python\Python313\site-packages\django\contrib\admin\sites.py", line 241, in inner
    return view(request, *args, **kwargs)
  File "C:\Users\krato\AppData\Roaming\Python\Python313\site-packages\django\utils\decorators.py", line 48, in _wrapper
    return bound_method(*args, **kwargs)
  File "C:\Users\krato\AppData\Roaming\Python\Python313\site-packages\django\views\decorators\debug.py", line 143, in sensitive_post_parameters_wrapper
    return view(request, *args, **kwargs)
  File "C:\Users\krato\AppData\Roaming\Python\Python313\site-packages\django\utils\decorators.py", line 48, in _wrapper
    return bound_method(*args, **kwargs)
  File "C:\Users\krato\AppData\Roaming\Python\Python313\site-packages\django\utils\decorators.py", line 188, in _view_wrapper
    result = _process_exception(request, e)
  File "C:\Users\krato\AppData\Roaming\Python\Python313\site-packages\django\utils\decorators.py", line 186, in _view_wrapper
    response = view_func(request, *args, **kwargs)
  File "C:\Users\krato\AppData\Roaming\Python\Python313\site-packages\django\contrib\auth\admin.py", line 121, in add_view
    return self._add_view(request, form_url, extra_context)
           ~~~~~~~~~~~~~~^^^^^^^^^^^^^^^^^^^^^^^^^^^^^^^^^^
  File "C:\Users\krato\AppData\Roaming\Python\Python313\site-packages\django\contrib\auth\admin.py", line 149, in _add_view
    return super().add_view(request, form_url, extra_context)
           ~~~~~~~~~~~~~~~~^^^^^^^^^^^^^^^^^^^^^^^^^^^^^^^^^^
  File "C:\Users\krato\AppData\Roaming\Python\Python313\site-packages\django\contrib\admin\options.py", line 1961, in add_view
    return self.changeform_view(request, None, form_url, extra_context)
           ~~~~~~~~~~~~~~~~~~~~^^^^^^^^^^^^^^^^^^^^^^^^^^^^^^^^^^^^^^^^
  File "C:\Users\krato\AppData\Roaming\Python\Python313\site-packages\django\utils\decorators.py", line 48, in _wrapper
    return bound_method(*args, **kwargs)
  File "C:\Users\krato\AppData\Roaming\Python\Python313\site-packages\django\utils\decorators.py", line 188, in _view_wrapper
    result = _process_exception(request, e)
  File "C:\Users\krato\AppData\Roaming\Python\Python313\site-packages\django\utils\decorators.py", line 186, in _view_wrapper
    response = view_func(request, *args, **kwargs)
  File "C:\Users\krato\AppData\Roaming\Python\Python313\site-packages\django\contrib\admin\options.py", line 1820, in changeform_view
    return self._changeform_view(request, object_id, form_url, extra_context)
           ~~~~~~~~~~~~~~~~~~~~~^^^^^^^^^^^^^^^^^^^^^^^^^^^^^^^^^^^^^^^^^^^^^
  File "C:\Users\krato\AppData\Roaming\Python\Python313\site-packages\django\contrib\admin\options.py", line 1871, in _changeform_view
    self.save_model(request, new_object, form, not add)
    ~~~~~~~~~~~~~~~^^^^^^^^^^^^^^^^^^^^^^^^^^^^^^^^^^^^
  File "C:\Users\krato\AppData\Roaming\Python\Python313\site-packages\django\contrib\admin\options.py", line 1294, in save_model
    obj.save()
    ~~~~~~~~^^
  File "C:\Users\krato\AppData\Roaming\Python\Python313\site-packages\django\contrib\auth\base_user.py", line 62, in save
    super().save(*args, **kwargs)
    ~~~~~~~~~~~~^^^^^^^^^^^^^^^^^
  File "C:\Users\krato\AppData\Roaming\Python\Python313\site-packages\django\db\models\base.py", line 891, in save
    self.save_base(
    ~~~~~~~~~~~~~~^
        using=using,
        ^^^^^^^^^^^^
    ...<2 lines>...
        update_fields=update_fields,
        ^^^^^^^^^^^^^^^^^^^^^^^^^^^^
    )
    ^
  File "C:\Users\krato\AppData\Roaming\Python\Python313\site-packages\django\db\models\base.py", line 1012, in save_base
    post_save.send(
    ~~~~~~~~~~~~~~^
        sender=origin,
        ^^^^^^^^^^^^^^
    ...<4 lines>...
        using=using,
        ^^^^^^^^^^^^
    )
    ^
  File "C:\Users\krato\AppData\Roaming\Python\Python313\site-packages\django\dispatch\dispatcher.py", line 189, in send
    response = receiver(signal=self, sender=sender, **named)
  File "C:\Users\krato\ssa_project\users\models.py", line 33, in create_user_profile
    Profile.objects.get_or_create(user=instance)  # Safely create the profile without duplicating
    ~~~~~~~~~~~~~~~~~~~~~~~~~~~~~^^^^^^^^^^^^^^^
  File "C:\Users\krato\AppData\Roaming\Python\Python313\site-packages\django\db\models\manager.py", line 87, in manager_method
    return getattr(self.get_queryset(), name)(*args, **kwargs)
           ~~~~~~~~~~~~~~~~~~~~~~~~~~~~~~~~~~^^^^^^^^^^^^^^^^^
  File "C:\Users\krato\AppData\Roaming\Python\Python313\site-packages\django\db\models\query.py", line 955, in get_or_create
    return self.create(**params), True
           ~~~~~~~~~~~^^^^^^^^^^
  File "C:\Users\krato\AppData\Roaming\Python\Python313\site-packages\django\db\models\query.py", line 679, in create
    obj.save(force_insert=True, using=self.db)
    ~~~~~~~~^^^^^^^^^^^^^^^^^^^^^^^^^^^^^^^^^^
  File "C:\Users\krato\ssa_project\users\models.py", line 19, in save
    self.clean()
    ~~~~~~~~~~^^
  File "C:\Users\krato\ssa_project\users\models.py", line 16, in clean
    validate_unique_nickname(self.nickname, instance=self)
    ~~~~~~~~~~~~~~~~~~~~~~~~^^^^^^^^^^^^^^^^^^^^^^^^^^^^^^
  File "C:\Users\krato\ssa_project\users\models.py", line 44, in validate_unique_nickname
    raise ValidationError(f"Nickname '{nickname}' is already taken.")
django.core.exceptions.ValidationError: ["Nickname '' is already taken."]
"POST /admin/auth/user/add/?_changelist_filters=q%3D HTTP/1.1" 500 219754
Internal Server Error: /admin/auth/user/add/
Traceback (most recent call last):
  File "C:\Users\krato\AppData\Roaming\Python\Python313\site-packages\django\db\models\query.py", line 948, in get_or_create
    return self.get(**kwargs), False
           ~~~~~~~~^^^^^^^^^^
  File "C:\Users\krato\AppData\Roaming\Python\Python313\site-packages\django\db\models\query.py", line 649, in get
    raise self.model.DoesNotExist(
        "%s matching query does not exist." % self.model._meta.object_name
    )
users.models.Profile.DoesNotExist: Profile matching query does not exist.

During handling of the above exception, another exception occurred:

Traceback (most recent call last):
  File "C:\Users\krato\AppData\Roaming\Python\Python313\site-packages\django\core\handlers\exception.py", line 55, in inner
    response = get_response(request)
  File "C:\Users\krato\AppData\Roaming\Python\Python313\site-packages\django\core\handlers\base.py", line 197, in _get_response
    response = wrapped_callback(request, *callback_args, **callback_kwargs)
  File "C:\Users\krato\AppData\Roaming\Python\Python313\site-packages\django\contrib\admin\options.py", line 718, in wrapper
    return self.admin_site.admin_view(view)(*args, **kwargs)
           ~~~~~~~~~~~~~~~~~~~~~~~~~~~~~~~~^^^^^^^^^^^^^^^^^
  File "C:\Users\krato\AppData\Roaming\Python\Python313\site-packages\django\utils\decorators.py", line 188, in _view_wrapper
    result = _process_exception(request, e)
  File "C:\Users\krato\AppData\Roaming\Python\Python313\site-packages\django\utils\decorators.py", line 186, in _view_wrapper
    response = view_func(request, *args, **kwargs)
  File "C:\Users\krato\AppData\Roaming\Python\Python313\site-packages\django\views\decorators\cache.py", line 80, in _view_wrapper
    response = view_func(request, *args, **kwargs)
  File "C:\Users\krato\AppData\Roaming\Python\Python313\site-packages\django\contrib\admin\sites.py", line 241, in inner
    return view(request, *args, **kwargs)
  File "C:\Users\krato\AppData\Roaming\Python\Python313\site-packages\django\utils\decorators.py", line 48, in _wrapper
    return bound_method(*args, **kwargs)
  File "C:\Users\krato\AppData\Roaming\Python\Python313\site-packages\django\views\decorators\debug.py", line 143, in sensitive_post_parameters_wrapper
    return view(request, *args, **kwargs)
  File "C:\Users\krato\AppData\Roaming\Python\Python313\site-packages\django\utils\decorators.py", line 48, in _wrapper
    return bound_method(*args, **kwargs)
  File "C:\Users\krato\AppData\Roaming\Python\Python313\site-packages\django\utils\decorators.py", line 188, in _view_wrapper
    result = _process_exception(request, e)
  File "C:\Users\krato\AppData\Roaming\Python\Python313\site-packages\django\utils\decorators.py", line 186, in _view_wrapper
    response = view_func(request, *args, **kwargs)
  File "C:\Users\krato\AppData\Roaming\Python\Python313\site-packages\django\contrib\auth\admin.py", line 121, in add_view
    return self._add_view(request, form_url, extra_context)
           ~~~~~~~~~~~~~~^^^^^^^^^^^^^^^^^^^^^^^^^^^^^^^^^^
  File "C:\Users\krato\AppData\Roaming\Python\Python313\site-packages\django\contrib\auth\admin.py", line 149, in _add_view
    return super().add_view(request, form_url, extra_context)
           ~~~~~~~~~~~~~~~~^^^^^^^^^^^^^^^^^^^^^^^^^^^^^^^^^^
  File "C:\Users\krato\AppData\Roaming\Python\Python313\site-packages\django\contrib\admin\options.py", line 1961, in add_view
    return self.changeform_view(request, None, form_url, extra_context)
           ~~~~~~~~~~~~~~~~~~~~^^^^^^^^^^^^^^^^^^^^^^^^^^^^^^^^^^^^^^^^
  File "C:\Users\krato\AppData\Roaming\Python\Python313\site-packages\django\utils\decorators.py", line 48, in _wrapper
    return bound_method(*args, **kwargs)
  File "C:\Users\krato\AppData\Roaming\Python\Python313\site-packages\django\utils\decorators.py", line 188, in _view_wrapper
    result = _process_exception(request, e)
  File "C:\Users\krato\AppData\Roaming\Python\Python313\site-packages\django\utils\decorators.py", line 186, in _view_wrapper
    response = view_func(request, *args, **kwargs)
  File "C:\Users\krato\AppData\Roaming\Python\Python313\site-packages\django\contrib\admin\options.py", line 1820, in changeform_view
    return self._changeform_view(request, object_id, form_url, extra_context)
           ~~~~~~~~~~~~~~~~~~~~~^^^^^^^^^^^^^^^^^^^^^^^^^^^^^^^^^^^^^^^^^^^^^
  File "C:\Users\krato\AppData\Roaming\Python\Python313\site-packages\django\contrib\admin\options.py", line 1871, in _changeform_view
    self.save_model(request, new_object, form, not add)
    ~~~~~~~~~~~~~~~^^^^^^^^^^^^^^^^^^^^^^^^^^^^^^^^^^^^
  File "C:\Users\krato\AppData\Roaming\Python\Python313\site-packages\django\contrib\admin\options.py", line 1294, in save_model
    obj.save()
    ~~~~~~~~^^
  File "C:\Users\krato\AppData\Roaming\Python\Python313\site-packages\django\contrib\auth\base_user.py", line 62, in save
    super().save(*args, **kwargs)
    ~~~~~~~~~~~~^^^^^^^^^^^^^^^^^
  File "C:\Users\krato\AppData\Roaming\Python\Python313\site-packages\django\db\models\base.py", line 891, in save
    self.save_base(
    ~~~~~~~~~~~~~~^
        using=using,
        ^^^^^^^^^^^^
    ...<2 lines>...
        update_fields=update_fields,
        ^^^^^^^^^^^^^^^^^^^^^^^^^^^^
    )
    ^
  File "C:\Users\krato\AppData\Roaming\Python\Python313\site-packages\django\db\models\base.py", line 1012, in save_base
    post_save.send(
    ~~~~~~~~~~~~~~^
        sender=origin,
        ^^^^^^^^^^^^^^
    ...<4 lines>...
        using=using,
        ^^^^^^^^^^^^
    )
    ^
  File "C:\Users\krato\AppData\Roaming\Python\Python313\site-packages\django\dispatch\dispatcher.py", line 189, in send
    response = receiver(signal=self, sender=sender, **named)
  File "C:\Users\krato\ssa_project\users\models.py", line 11, in create_user_profile
    Profile.objects.get_or_create(user=instance)  # Safely create the profile without duplicating
    ~~~~~~~~~~~~~~~~~~~~~~~~~~~~~^^^^^^^^^^^^^^^
  File "C:\Users\krato\AppData\Roaming\Python\Python313\site-packages\django\db\models\manager.py", line 87, in manager_method
    return getattr(self.get_queryset(), name)(*args, **kwargs)
           ~~~~~~~~~~~~~~~~~~~~~~~~~~~~~~~~~~^^^^^^^^^^^^^^^^^
  File "C:\Users\krato\AppData\Roaming\Python\Python313\site-packages\django\db\models\query.py", line 955, in get_or_create
    return self.create(**params), True
           ~~~~~~~~~~~^^^^^^^^^^
  File "C:\Users\krato\AppData\Roaming\Python\Python313\site-packages\django\db\models\query.py", line 679, in create
    obj.save(force_insert=True, using=self.db)
    ~~~~~~~~^^^^^^^^^^^^^^^^^^^^^^^^^^^^^^^^^^
  File "C:\Users\krato\ssa_project\users\models.py", line 35, in save
    self.clean()
    ~~~~~~~~~~^^
  File "C:\Users\krato\ssa_project\users\models.py", line 33, in clean
    validate_unique_nickname(self.nickname, instance=self)
    ~~~~~~~~~~~~~~~~~~~~~~~~^^^^^^^^^^^^^^^^^^^^^^^^^^^^^^
  File "C:\Users\krato\ssa_project\users\models.py", line 22, in validate_unique_nickname
    raise ValidationError(f"Nickname '{nickname}' is already taken.")
django.core.exceptions.ValidationError: ["Nickname '' is already taken."]
"POST /admin/auth/user/add/?_changelist_filters=q%3D HTTP/1.1" 500 219694
Internal Server Error: /admin/auth/user/add/
Traceback (most recent call last):
  File "C:\Users\krato\AppData\Roaming\Python\Python313\site-packages\django\db\models\query.py", line 948, in get_or_create
    return self.get(**kwargs), False
           ~~~~~~~~^^^^^^^^^^
  File "C:\Users\krato\AppData\Roaming\Python\Python313\site-packages\django\db\models\query.py", line 649, in get
    raise self.model.DoesNotExist(
        "%s matching query does not exist." % self.model._meta.object_name
    )
users.models.Profile.DoesNotExist: Profile matching query does not exist.

During handling of the above exception, another exception occurred:

Traceback (most recent call last):
  File "C:\Users\krato\AppData\Roaming\Python\Python313\site-packages\django\core\handlers\exception.py", line 55, in inner
    response = get_response(request)
  File "C:\Users\krato\AppData\Roaming\Python\Python313\site-packages\django\core\handlers\base.py", line 197, in _get_response
    response = wrapped_callback(request, *callback_args, **callback_kwargs)
  File "C:\Users\krato\AppData\Roaming\Python\Python313\site-packages\django\contrib\admin\options.py", line 718, in wrapper
    return self.admin_site.admin_view(view)(*args, **kwargs)
           ~~~~~~~~~~~~~~~~~~~~~~~~~~~~~~~~^^^^^^^^^^^^^^^^^
  File "C:\Users\krato\AppData\Roaming\Python\Python313\site-packages\django\utils\decorators.py", line 188, in _view_wrapper
    result = _process_exception(request, e)
  File "C:\Users\krato\AppData\Roaming\Python\Python313\site-packages\django\utils\decorators.py", line 186, in _view_wrapper
    response = view_func(request, *args, **kwargs)
  File "C:\Users\krato\AppData\Roaming\Python\Python313\site-packages\django\views\decorators\cache.py", line 80, in _view_wrapper
    response = view_func(request, *args, **kwargs)
  File "C:\Users\krato\AppData\Roaming\Python\Python313\site-packages\django\contrib\admin\sites.py", line 241, in inner
    return view(request, *args, **kwargs)
  File "C:\Users\krato\AppData\Roaming\Python\Python313\site-packages\django\utils\decorators.py", line 48, in _wrapper
    return bound_method(*args, **kwargs)
  File "C:\Users\krato\AppData\Roaming\Python\Python313\site-packages\django\views\decorators\debug.py", line 143, in sensitive_post_parameters_wrapper
    return view(request, *args, **kwargs)
  File "C:\Users\krato\AppData\Roaming\Python\Python313\site-packages\django\utils\decorators.py", line 48, in _wrapper
    return bound_method(*args, **kwargs)
  File "C:\Users\krato\AppData\Roaming\Python\Python313\site-packages\django\utils\decorators.py", line 188, in _view_wrapper
    result = _process_exception(request, e)
  File "C:\Users\krato\AppData\Roaming\Python\Python313\site-packages\django\utils\decorators.py", line 186, in _view_wrapper
    response = view_func(request, *args, **kwargs)
  File "C:\Users\krato\AppData\Roaming\Python\Python313\site-packages\django\contrib\auth\admin.py", line 121, in add_view
    return self._add_view(request, form_url, extra_context)
           ~~~~~~~~~~~~~~^^^^^^^^^^^^^^^^^^^^^^^^^^^^^^^^^^
  File "C:\Users\krato\AppData\Roaming\Python\Python313\site-packages\django\contrib\auth\admin.py", line 149, in _add_view
    return super().add_view(request, form_url, extra_context)
           ~~~~~~~~~~~~~~~~^^^^^^^^^^^^^^^^^^^^^^^^^^^^^^^^^^
  File "C:\Users\krato\AppData\Roaming\Python\Python313\site-packages\django\contrib\admin\options.py", line 1961, in add_view
    return self.changeform_view(request, None, form_url, extra_context)
           ~~~~~~~~~~~~~~~~~~~~^^^^^^^^^^^^^^^^^^^^^^^^^^^^^^^^^^^^^^^^
  File "C:\Users\krato\AppData\Roaming\Python\Python313\site-packages\django\utils\decorators.py", line 48, in _wrapper
    return bound_method(*args, **kwargs)
  File "C:\Users\krato\AppData\Roaming\Python\Python313\site-packages\django\utils\decorators.py", line 188, in _view_wrapper
    result = _process_exception(request, e)
  File "C:\Users\krato\AppData\Roaming\Python\Python313\site-packages\django\utils\decorators.py", line 186, in _view_wrapper
    response = view_func(request, *args, **kwargs)
  File "C:\Users\krato\AppData\Roaming\Python\Python313\site-packages\django\contrib\admin\options.py", line 1820, in changeform_view
    return self._changeform_view(request, object_id, form_url, extra_context)
           ~~~~~~~~~~~~~~~~~~~~~^^^^^^^^^^^^^^^^^^^^^^^^^^^^^^^^^^^^^^^^^^^^^
  File "C:\Users\krato\AppData\Roaming\Python\Python313\site-packages\django\contrib\admin\options.py", line 1871, in _changeform_view
    self.save_model(request, new_object, form, not add)
    ~~~~~~~~~~~~~~~^^^^^^^^^^^^^^^^^^^^^^^^^^^^^^^^^^^^
  File "C:\Users\krato\AppData\Roaming\Python\Python313\site-packages\django\contrib\admin\options.py", line 1294, in save_model
    obj.save()
    ~~~~~~~~^^
  File "C:\Users\krato\AppData\Roaming\Python\Python313\site-packages\django\contrib\auth\base_user.py", line 62, in save
    super().save(*args, **kwargs)
    ~~~~~~~~~~~~^^^^^^^^^^^^^^^^^
  File "C:\Users\krato\AppData\Roaming\Python\Python313\site-packages\django\db\models\base.py", line 891, in save
    self.save_base(
    ~~~~~~~~~~~~~~^
        using=using,
        ^^^^^^^^^^^^
    ...<2 lines>...
        update_fields=update_fields,
        ^^^^^^^^^^^^^^^^^^^^^^^^^^^^
    )
    ^
  File "C:\Users\krato\AppData\Roaming\Python\Python313\site-packages\django\db\models\base.py", line 1012, in save_base
    post_save.send(
    ~~~~~~~~~~~~~~^
        sender=origin,
        ^^^^^^^^^^^^^^
    ...<4 lines>...
        using=using,
        ^^^^^^^^^^^^
    )
    ^
  File "C:\Users\krato\AppData\Roaming\Python\Python313\site-packages\django\dispatch\dispatcher.py", line 189, in send
    response = receiver(signal=self, sender=sender, **named)
  File "C:\Users\krato\ssa_project\users\models.py", line 11, in create_user_profile
    Profile.objects.get_or_create(user=instance)  # Safely create the profile without duplicating
    ~~~~~~~~~~~~~~~~~~~~~~~~~~~~~^^^^^^^^^^^^^^^
  File "C:\Users\krato\AppData\Roaming\Python\Python313\site-packages\django\db\models\manager.py", line 87, in manager_method
    return getattr(self.get_queryset(), name)(*args, **kwargs)
           ~~~~~~~~~~~~~~~~~~~~~~~~~~~~~~~~~~^^^^^^^^^^^^^^^^^
  File "C:\Users\krato\AppData\Roaming\Python\Python313\site-packages\django\db\models\query.py", line 955, in get_or_create
    return self.create(**params), True
           ~~~~~~~~~~~^^^^^^^^^^
  File "C:\Users\krato\AppData\Roaming\Python\Python313\site-packages\django\db\models\query.py", line 679, in create
    obj.save(force_insert=True, using=self.db)
    ~~~~~~~~^^^^^^^^^^^^^^^^^^^^^^^^^^^^^^^^^^
  File "C:\Users\krato\ssa_project\users\models.py", line 35, in save
    self.clean()
    ~~~~~~~~~~^^
  File "C:\Users\krato\ssa_project\users\models.py", line 33, in clean
    validate_unique_nickname(self.nickname, instance=self)
    ~~~~~~~~~~~~~~~~~~~~~~~~^^^^^^^^^^^^^^^^^^^^^^^^^^^^^^
  File "C:\Users\krato\ssa_project\users\models.py", line 22, in validate_unique_nickname
    raise ValidationError(f"Nickname '{nickname}' is already taken.")
django.core.exceptions.ValidationError: ["Nickname '' is already taken."]
"POST /admin/auth/user/add/?_changelist_filters=q%3D HTTP/1.1" 500 219713
Internal Server Error: /admin/auth/user/add/
Traceback (most recent call last):
  File "C:\Users\krato\AppData\Roaming\Python\Python313\site-packages\django\db\models\query.py", line 948, in get_or_create
    return self.get(**kwargs), False
           ~~~~~~~~^^^^^^^^^^
  File "C:\Users\krato\AppData\Roaming\Python\Python313\site-packages\django\db\models\query.py", line 649, in get
    raise self.model.DoesNotExist(
        "%s matching query does not exist." % self.model._meta.object_name
    )
users.models.Profile.DoesNotExist: Profile matching query does not exist.

During handling of the above exception, another exception occurred:

Traceback (most recent call last):
  File "C:\Users\krato\AppData\Roaming\Python\Python313\site-packages\django\core\handlers\exception.py", line 55, in inner
    response = get_response(request)
  File "C:\Users\krato\AppData\Roaming\Python\Python313\site-packages\django\core\handlers\base.py", line 197, in _get_response
    response = wrapped_callback(request, *callback_args, **callback_kwargs)
  File "C:\Users\krato\AppData\Roaming\Python\Python313\site-packages\django\contrib\admin\options.py", line 718, in wrapper
    return self.admin_site.admin_view(view)(*args, **kwargs)
           ~~~~~~~~~~~~~~~~~~~~~~~~~~~~~~~~^^^^^^^^^^^^^^^^^
  File "C:\Users\krato\AppData\Roaming\Python\Python313\site-packages\django\utils\decorators.py", line 188, in _view_wrapper
    result = _process_exception(request, e)
  File "C:\Users\krato\AppData\Roaming\Python\Python313\site-packages\django\utils\decorators.py", line 186, in _view_wrapper
    response = view_func(request, *args, **kwargs)
  File "C:\Users\krato\AppData\Roaming\Python\Python313\site-packages\django\views\decorators\cache.py", line 80, in _view_wrapper
    response = view_func(request, *args, **kwargs)
  File "C:\Users\krato\AppData\Roaming\Python\Python313\site-packages\django\contrib\admin\sites.py", line 241, in inner
    return view(request, *args, **kwargs)
  File "C:\Users\krato\AppData\Roaming\Python\Python313\site-packages\django\utils\decorators.py", line 48, in _wrapper
    return bound_method(*args, **kwargs)
  File "C:\Users\krato\AppData\Roaming\Python\Python313\site-packages\django\views\decorators\debug.py", line 143, in sensitive_post_parameters_wrapper
    return view(request, *args, **kwargs)
  File "C:\Users\krato\AppData\Roaming\Python\Python313\site-packages\django\utils\decorators.py", line 48, in _wrapper
    return bound_method(*args, **kwargs)
  File "C:\Users\krato\AppData\Roaming\Python\Python313\site-packages\django\utils\decorators.py", line 188, in _view_wrapper
    result = _process_exception(request, e)
  File "C:\Users\krato\AppData\Roaming\Python\Python313\site-packages\django\utils\decorators.py", line 186, in _view_wrapper
    response = view_func(request, *args, **kwargs)
  File "C:\Users\krato\AppData\Roaming\Python\Python313\site-packages\django\contrib\auth\admin.py", line 121, in add_view
    return self._add_view(request, form_url, extra_context)
           ~~~~~~~~~~~~~~^^^^^^^^^^^^^^^^^^^^^^^^^^^^^^^^^^
  File "C:\Users\krato\AppData\Roaming\Python\Python313\site-packages\django\contrib\auth\admin.py", line 149, in _add_view
    return super().add_view(request, form_url, extra_context)
           ~~~~~~~~~~~~~~~~^^^^^^^^^^^^^^^^^^^^^^^^^^^^^^^^^^
  File "C:\Users\krato\AppData\Roaming\Python\Python313\site-packages\django\contrib\admin\options.py", line 1961, in add_view
    return self.changeform_view(request, None, form_url, extra_context)
           ~~~~~~~~~~~~~~~~~~~~^^^^^^^^^^^^^^^^^^^^^^^^^^^^^^^^^^^^^^^^
  File "C:\Users\krato\AppData\Roaming\Python\Python313\site-packages\django\utils\decorators.py", line 48, in _wrapper
    return bound_method(*args, **kwargs)
  File "C:\Users\krato\AppData\Roaming\Python\Python313\site-packages\django\utils\decorators.py", line 188, in _view_wrapper
    result = _process_exception(request, e)
  File "C:\Users\krato\AppData\Roaming\Python\Python313\site-packages\django\utils\decorators.py", line 186, in _view_wrapper
    response = view_func(request, *args, **kwargs)
  File "C:\Users\krato\AppData\Roaming\Python\Python313\site-packages\django\contrib\admin\options.py", line 1820, in changeform_view
    return self._changeform_view(request, object_id, form_url, extra_context)
           ~~~~~~~~~~~~~~~~~~~~~^^^^^^^^^^^^^^^^^^^^^^^^^^^^^^^^^^^^^^^^^^^^^
  File "C:\Users\krato\AppData\Roaming\Python\Python313\site-packages\django\contrib\admin\options.py", line 1871, in _changeform_view
    self.save_model(request, new_object, form, not add)
    ~~~~~~~~~~~~~~~^^^^^^^^^^^^^^^^^^^^^^^^^^^^^^^^^^^^
  File "C:\Users\krato\AppData\Roaming\Python\Python313\site-packages\django\contrib\admin\options.py", line 1294, in save_model
    obj.save()
    ~~~~~~~~^^
  File "C:\Users\krato\AppData\Roaming\Python\Python313\site-packages\django\contrib\auth\base_user.py", line 62, in save
    super().save(*args, **kwargs)
    ~~~~~~~~~~~~^^^^^^^^^^^^^^^^^
  File "C:\Users\krato\AppData\Roaming\Python\Python313\site-packages\django\db\models\base.py", line 891, in save
    self.save_base(
    ~~~~~~~~~~~~~~^
        using=using,
        ^^^^^^^^^^^^
    ...<2 lines>...
        update_fields=update_fields,
        ^^^^^^^^^^^^^^^^^^^^^^^^^^^^
    )
    ^
  File "C:\Users\krato\AppData\Roaming\Python\Python313\site-packages\django\db\models\base.py", line 1012, in save_base
    post_save.send(
    ~~~~~~~~~~~~~~^
        sender=origin,
        ^^^^^^^^^^^^^^
    ...<4 lines>...
        using=using,
        ^^^^^^^^^^^^
    )
    ^
  File "C:\Users\krato\AppData\Roaming\Python\Python313\site-packages\django\dispatch\dispatcher.py", line 189, in send
    response = receiver(signal=self, sender=sender, **named)
  File "C:\Users\krato\ssa_project\users\models.py", line 11, in create_user_profile
    Profile.objects.get_or_create(user=instance)  # Safely create the profile without duplicating
    ~~~~~~~~~~~~~~~~~~~~~~~~~~~~~^^^^^^^^^^^^^^^
  File "C:\Users\krato\AppData\Roaming\Python\Python313\site-packages\django\db\models\manager.py", line 87, in manager_method
    return getattr(self.get_queryset(), name)(*args, **kwargs)
           ~~~~~~~~~~~~~~~~~~~~~~~~~~~~~~~~~~^^^^^^^^^^^^^^^^^
  File "C:\Users\krato\AppData\Roaming\Python\Python313\site-packages\django\db\models\query.py", line 955, in get_or_create
    return self.create(**params), True
           ~~~~~~~~~~~^^^^^^^^^^
  File "C:\Users\krato\AppData\Roaming\Python\Python313\site-packages\django\db\models\query.py", line 679, in create
    obj.save(force_insert=True, using=self.db)
    ~~~~~~~~^^^^^^^^^^^^^^^^^^^^^^^^^^^^^^^^^^
  File "C:\Users\krato\ssa_project\users\models.py", line 49, in save
    self.clean()
    ~~~~~~~~~~^^
  File "C:\Users\krato\ssa_project\users\models.py", line 47, in clean
    validate_unique_nickname(self.nickname, instance=self)
    ~~~~~~~~~~~~~~~~~~~~~~~~^^^^^^^^^^^^^^^^^^^^^^^^^^^^^^
  File "C:\Users\krato\ssa_project\users\models.py", line 28, in validate_unique_nickname
    raise ValidationError("Nickname cannot be empty.")
django.core.exceptions.ValidationError: ['Nickname cannot be empty.']
"POST /admin/auth/user/add/?_changelist_filters=q%3D HTTP/1.1" 500 219448
Internal Server Error: /admin/auth/user/add/
Traceback (most recent call last):
  File "C:\Users\krato\AppData\Roaming\Python\Python313\site-packages\django\db\models\query.py", line 948, in get_or_create
    return self.get(**kwargs), False
           ~~~~~~~~^^^^^^^^^^
  File "C:\Users\krato\AppData\Roaming\Python\Python313\site-packages\django\db\models\query.py", line 649, in get
    raise self.model.DoesNotExist(
        "%s matching query does not exist." % self.model._meta.object_name
    )
users.models.Profile.DoesNotExist: Profile matching query does not exist.

During handling of the above exception, another exception occurred:

Traceback (most recent call last):
  File "C:\Users\krato\AppData\Roaming\Python\Python313\site-packages\django\db\backends\utils.py", line 105, in _execute
    return self.cursor.execute(sql, params)
           ~~~~~~~~~~~~~~~~~~~^^^^^^^^^^^^^
  File "C:\Users\krato\AppData\Roaming\Python\Python313\site-packages\django\db\backends\sqlite3\base.py", line 354, in execute
    return super().execute(query, params)
           ~~~~~~~~~~~~~~~^^^^^^^^^^^^^^^
sqlite3.IntegrityError: NOT NULL constraint failed: users_profile.balance

The above exception was the direct cause of the following exception:

Traceback (most recent call last):
  File "C:\Users\krato\AppData\Roaming\Python\Python313\site-packages\django\core\handlers\exception.py", line 55, in inner
    response = get_response(request)
  File "C:\Users\krato\AppData\Roaming\Python\Python313\site-packages\django\core\handlers\base.py", line 197, in _get_response
    response = wrapped_callback(request, *callback_args, **callback_kwargs)
  File "C:\Users\krato\AppData\Roaming\Python\Python313\site-packages\django\contrib\admin\options.py", line 718, in wrapper
    return self.admin_site.admin_view(view)(*args, **kwargs)
           ~~~~~~~~~~~~~~~~~~~~~~~~~~~~~~~~^^^^^^^^^^^^^^^^^
  File "C:\Users\krato\AppData\Roaming\Python\Python313\site-packages\django\utils\decorators.py", line 188, in _view_wrapper
    result = _process_exception(request, e)
  File "C:\Users\krato\AppData\Roaming\Python\Python313\site-packages\django\utils\decorators.py", line 186, in _view_wrapper
    response = view_func(request, *args, **kwargs)
  File "C:\Users\krato\AppData\Roaming\Python\Python313\site-packages\django\views\decorators\cache.py", line 80, in _view_wrapper
    response = view_func(request, *args, **kwargs)
  File "C:\Users\krato\AppData\Roaming\Python\Python313\site-packages\django\contrib\admin\sites.py", line 241, in inner
    return view(request, *args, **kwargs)
  File "C:\Users\krato\AppData\Roaming\Python\Python313\site-packages\django\utils\decorators.py", line 48, in _wrapper
    return bound_method(*args, **kwargs)
  File "C:\Users\krato\AppData\Roaming\Python\Python313\site-packages\django\views\decorators\debug.py", line 143, in sensitive_post_parameters_wrapper
    return view(request, *args, **kwargs)
  File "C:\Users\krato\AppData\Roaming\Python\Python313\site-packages\django\utils\decorators.py", line 48, in _wrapper
    return bound_method(*args, **kwargs)
  File "C:\Users\krato\AppData\Roaming\Python\Python313\site-packages\django\utils\decorators.py", line 188, in _view_wrapper
    result = _process_exception(request, e)
  File "C:\Users\krato\AppData\Roaming\Python\Python313\site-packages\django\utils\decorators.py", line 186, in _view_wrapper
    response = view_func(request, *args, **kwargs)
  File "C:\Users\krato\AppData\Roaming\Python\Python313\site-packages\django\contrib\auth\admin.py", line 121, in add_view
    return self._add_view(request, form_url, extra_context)
           ~~~~~~~~~~~~~~^^^^^^^^^^^^^^^^^^^^^^^^^^^^^^^^^^
  File "C:\Users\krato\AppData\Roaming\Python\Python313\site-packages\django\contrib\auth\admin.py", line 149, in _add_view
    return super().add_view(request, form_url, extra_context)
           ~~~~~~~~~~~~~~~~^^^^^^^^^^^^^^^^^^^^^^^^^^^^^^^^^^
  File "C:\Users\krato\AppData\Roaming\Python\Python313\site-packages\django\contrib\admin\options.py", line 1961, in add_view
    return self.changeform_view(request, None, form_url, extra_context)
           ~~~~~~~~~~~~~~~~~~~~^^^^^^^^^^^^^^^^^^^^^^^^^^^^^^^^^^^^^^^^
  File "C:\Users\krato\AppData\Roaming\Python\Python313\site-packages\django\utils\decorators.py", line 48, in _wrapper
    return bound_method(*args, **kwargs)
  File "C:\Users\krato\AppData\Roaming\Python\Python313\site-packages\django\utils\decorators.py", line 188, in _view_wrapper
    result = _process_exception(request, e)
  File "C:\Users\krato\AppData\Roaming\Python\Python313\site-packages\django\utils\decorators.py", line 186, in _view_wrapper
    response = view_func(request, *args, **kwargs)
  File "C:\Users\krato\AppData\Roaming\Python\Python313\site-packages\django\contrib\admin\options.py", line 1820, in changeform_view
    return self._changeform_view(request, object_id, form_url, extra_context)
           ~~~~~~~~~~~~~~~~~~~~~^^^^^^^^^^^^^^^^^^^^^^^^^^^^^^^^^^^^^^^^^^^^^
  File "C:\Users\krato\AppData\Roaming\Python\Python313\site-packages\django\contrib\admin\options.py", line 1871, in _changeform_view
    self.save_model(request, new_object, form, not add)
    ~~~~~~~~~~~~~~~^^^^^^^^^^^^^^^^^^^^^^^^^^^^^^^^^^^^
  File "C:\Users\krato\AppData\Roaming\Python\Python313\site-packages\django\contrib\admin\options.py", line 1294, in save_model
    obj.save()
    ~~~~~~~~^^
  File "C:\Users\krato\AppData\Roaming\Python\Python313\site-packages\django\contrib\auth\base_user.py", line 62, in save
    super().save(*args, **kwargs)
    ~~~~~~~~~~~~^^^^^^^^^^^^^^^^^
  File "C:\Users\krato\AppData\Roaming\Python\Python313\site-packages\django\db\models\base.py", line 891, in save
    self.save_base(
    ~~~~~~~~~~~~~~^
        using=using,
        ^^^^^^^^^^^^
    ...<2 lines>...
        update_fields=update_fields,
        ^^^^^^^^^^^^^^^^^^^^^^^^^^^^
    )
    ^
  File "C:\Users\krato\AppData\Roaming\Python\Python313\site-packages\django\db\models\base.py", line 1012, in save_base
    post_save.send(
    ~~~~~~~~~~~~~~^
        sender=origin,
        ^^^^^^^^^^^^^^
    ...<4 lines>...
        using=using,
        ^^^^^^^^^^^^
    )
    ^
  File "C:\Users\krato\AppData\Roaming\Python\Python313\site-packages\django\dispatch\dispatcher.py", line 189, in send
    response = receiver(signal=self, sender=sender, **named)
  File "C:\Users\krato\ssa_project\users\models.py", line 12, in create_user_profile
    Profile.objects.get_or_create(user=instance, defaults={'nickname': f"user_{instance.id}"})
    ~~~~~~~~~~~~~~~~~~~~~~~~~~~~~^^^^^^^^^^^^^^^^^^^^^^^^^^^^^^^^^^^^^^^^^^^^^^^^^^^^^^^^^^^^^
  File "C:\Users\krato\AppData\Roaming\Python\Python313\site-packages\django\db\models\manager.py", line 87, in manager_method
    return getattr(self.get_queryset(), name)(*args, **kwargs)
           ~~~~~~~~~~~~~~~~~~~~~~~~~~~~~~~~~~^^^^^^^^^^^^^^^^^
  File "C:\Users\krato\AppData\Roaming\Python\Python313\site-packages\django\db\models\query.py", line 955, in get_or_create
    return self.create(**params), True
           ~~~~~~~~~~~^^^^^^^^^^
  File "C:\Users\krato\AppData\Roaming\Python\Python313\site-packages\django\db\models\query.py", line 679, in create
    obj.save(force_insert=True, using=self.db)
    ~~~~~~~~^^^^^^^^^^^^^^^^^^^^^^^^^^^^^^^^^^
  File "C:\Users\krato\ssa_project\users\models.py", line 53, in save
    super().save(*args, **kwargs)
    ~~~~~~~~~~~~^^^^^^^^^^^^^^^^^
  File "C:\Users\krato\AppData\Roaming\Python\Python313\site-packages\django\db\models\base.py", line 891, in save
    self.save_base(
    ~~~~~~~~~~~~~~^
        using=using,
        ^^^^^^^^^^^^
    ...<2 lines>...
        update_fields=update_fields,
        ^^^^^^^^^^^^^^^^^^^^^^^^^^^^
    )
    ^
  File "C:\Users\krato\AppData\Roaming\Python\Python313\site-packages\django\db\models\base.py", line 997, in save_base
    updated = self._save_table(
        raw,
    ...<4 lines>...
        update_fields,
    )
  File "C:\Users\krato\AppData\Roaming\Python\Python313\site-packages\django\db\models\base.py", line 1160, in _save_table
    results = self._do_insert(
        cls._base_manager, using, fields, returning_fields, raw
    )
  File "C:\Users\krato\AppData\Roaming\Python\Python313\site-packages\django\db\models\base.py", line 1201, in _do_insert
    return manager._insert(
           ~~~~~~~~~~~~~~~^
        [self],
        ^^^^^^^
    ...<3 lines>...
        raw=raw,
        ^^^^^^^^
    )
    ^
  File "C:\Users\krato\AppData\Roaming\Python\Python313\site-packages\django\db\models\manager.py", line 87, in manager_method
    return getattr(self.get_queryset(), name)(*args, **kwargs)
           ~~~~~~~~~~~~~~~~~~~~~~~~~~~~~~~~~~^^^^^^^^^^^^^^^^^
  File "C:\Users\krato\AppData\Roaming\Python\Python313\site-packages\django\db\models\query.py", line 1847, in _insert
    return query.get_compiler(using=using).execute_sql(returning_fields)
           ~~~~~~~~~~~~~~~~~~~~~~~~~~~~~~~~~~~~~~~~~~~^^^^^^^^^^^^^^^^^^
  File "C:\Users\krato\AppData\Roaming\Python\Python313\site-packages\django\db\models\sql\compiler.py", line 1836, in execute_sql
    cursor.execute(sql, params)
    ~~~~~~~~~~~~~~^^^^^^^^^^^^^
  File "C:\Users\krato\AppData\Roaming\Python\Python313\site-packages\django\db\backends\utils.py", line 122, in execute
    return super().execute(sql, params)
           ~~~~~~~~~~~~~~~^^^^^^^^^^^^^
  File "C:\Users\krato\AppData\Roaming\Python\Python313\site-packages\django\db\backends\utils.py", line 79, in execute
    return self._execute_with_wrappers(
           ~~~~~~~~~~~~~~~~~~~~~~~~~~~^
        sql, params, many=False, executor=self._execute
        ^^^^^^^^^^^^^^^^^^^^^^^^^^^^^^^^^^^^^^^^^^^^^^^
    )
    ^
  File "C:\Users\krato\AppData\Roaming\Python\Python313\site-packages\django\db\backends\utils.py", line 92, in _execute_with_wrappers
    return executor(sql, params, many, context)
  File "C:\Users\krato\AppData\Roaming\Python\Python313\site-packages\django\db\backends\utils.py", line 100, in _execute
    with self.db.wrap_database_errors:
         ^^^^^^^^^^^^^^^^^^^^^^^^^^^^
  File "C:\Users\krato\AppData\Roaming\Python\Python313\site-packages\django\db\utils.py", line 91, in __exit__
    raise dj_exc_value.with_traceback(traceback) from exc_value
  File "C:\Users\krato\AppData\Roaming\Python\Python313\site-packages\django\db\backends\utils.py", line 105, in _execute
    return self.cursor.execute(sql, params)
           ~~~~~~~~~~~~~~~~~~~^^^^^^^^^^^^^
  File "C:\Users\krato\AppData\Roaming\Python\Python313\site-packages\django\db\backends\sqlite3\base.py", line 354, in execute
    return super().execute(query, params)
           ~~~~~~~~~~~~~~~^^^^^^^^^^^^^^^
django.db.utils.IntegrityError: NOT NULL constraint failed: users_profile.balance
"POST /admin/auth/user/add/?_changelist_filters=q%3D HTTP/1.1" 500 293762
Internal Server Error: /users/register/
Traceback (most recent call last):
  File "C:\Users\krato\AppData\Roaming\Python\Python313\site-packages\django\db\models\query.py", line 948, in get_or_create
    return self.get(**kwargs), False
           ~~~~~~~~^^^^^^^^^^
  File "C:\Users\krato\AppData\Roaming\Python\Python313\site-packages\django\db\models\query.py", line 649, in get
    raise self.model.DoesNotExist(
        "%s matching query does not exist." % self.model._meta.object_name
    )
users.models.Profile.DoesNotExist: Profile matching query does not exist.

During handling of the above exception, another exception occurred:

Traceback (most recent call last):
  File "C:\Users\krato\AppData\Roaming\Python\Python313\site-packages\django\core\handlers\exception.py", line 55, in inner
    response = get_response(request)
  File "C:\Users\krato\AppData\Roaming\Python\Python313\site-packages\django\core\handlers\base.py", line 197, in _get_response
    response = wrapped_callback(request, *callback_args, **callback_kwargs)
  File "C:\Users\krato\ssa_project\users\views.py", line 16, in register
    form.save()
    ~~~~~~~~~^^
  File "C:\Users\krato\ssa_project\users\forms.py", line 22, in save
    user.save()
    ~~~~~~~~~^^
  File "C:\Users\krato\AppData\Roaming\Python\Python313\site-packages\django\contrib\auth\base_user.py", line 62, in save
    super().save(*args, **kwargs)
    ~~~~~~~~~~~~^^^^^^^^^^^^^^^^^
  File "C:\Users\krato\AppData\Roaming\Python\Python313\site-packages\django\db\models\base.py", line 891, in save
    self.save_base(
    ~~~~~~~~~~~~~~^
        using=using,
        ^^^^^^^^^^^^
    ...<2 lines>...
        update_fields=update_fields,
        ^^^^^^^^^^^^^^^^^^^^^^^^^^^^
    )
    ^
  File "C:\Users\krato\AppData\Roaming\Python\Python313\site-packages\django\db\models\base.py", line 1012, in save_base
    post_save.send(
    ~~~~~~~~~~~~~~^
        sender=origin,
        ^^^^^^^^^^^^^^
    ...<4 lines>...
        using=using,
        ^^^^^^^^^^^^
    )
    ^
  File "C:\Users\krato\AppData\Roaming\Python\Python313\site-packages\django\dispatch\dispatcher.py", line 189, in send
    response = receiver(signal=self, sender=sender, **named)
  File "C:\Users\krato\ssa_project\users\models.py", line 12, in create_user_profile
    Profile.objects.get_or_create(user=instance)  # Safely create the profile without duplicating
    ~~~~~~~~~~~~~~~~~~~~~~~~~~~~~^^^^^^^^^^^^^^^
  File "C:\Users\krato\AppData\Roaming\Python\Python313\site-packages\django\db\models\manager.py", line 87, in manager_method
    return getattr(self.get_queryset(), name)(*args, **kwargs)
           ~~~~~~~~~~~~~~~~~~~~~~~~~~~~~~~~~~^^^^^^^^^^^^^^^^^
  File "C:\Users\krato\AppData\Roaming\Python\Python313\site-packages\django\db\models\query.py", line 955, in get_or_create
    return self.create(**params), True
           ~~~~~~~~~~~^^^^^^^^^^
  File "C:\Users\krato\AppData\Roaming\Python\Python313\site-packages\django\db\models\query.py", line 679, in create
    obj.save(force_insert=True, using=self.db)
    ~~~~~~~~^^^^^^^^^^^^^^^^^^^^^^^^^^^^^^^^^^
  File "C:\Users\krato\ssa_project\users\models.py", line 41, in save
    self.clean()
    ~~~~~~~~~~^^
  File "C:\Users\krato\ssa_project\users\models.py", line 38, in clean
    validate_unique_nickname(self.nickname, instance=self)
    ~~~~~~~~~~~~~~~~~~~~~~~~^^^^^^^^^^^^^^^^^^^^^^^^^^^^^^
  File "C:\Users\krato\ssa_project\users\models.py", line 23, in validate_unique_nickname
    raise ValidationError(f"Nickname '{nickname}' is already taken.")
django.core.exceptions.ValidationError: ["Nickname '' is already taken."]
"POST /users/register/ HTTP/1.1" 500 129101
Internal Server Error: /users/register/
Traceback (most recent call last):
  File "C:\Users\krato\AppData\Roaming\Python\Python313\site-packages\django\db\models\query.py", line 948, in get_or_create
    return self.get(**kwargs), False
           ~~~~~~~~^^^^^^^^^^
  File "C:\Users\krato\AppData\Roaming\Python\Python313\site-packages\django\db\models\query.py", line 649, in get
    raise self.model.DoesNotExist(
        "%s matching query does not exist." % self.model._meta.object_name
    )
users.models.Profile.DoesNotExist: Profile matching query does not exist.

During handling of the above exception, another exception occurred:

Traceback (most recent call last):
  File "C:\Users\krato\AppData\Roaming\Python\Python313\site-packages\django\core\handlers\exception.py", line 55, in inner
    response = get_response(request)
  File "C:\Users\krato\AppData\Roaming\Python\Python313\site-packages\django\core\handlers\base.py", line 197, in _get_response
    response = wrapped_callback(request, *callback_args, **callback_kwargs)
  File "C:\Users\krato\ssa_project\users\views.py", line 16, in register
    form.save()
    ~~~~~~~~~^^
  File "C:\Users\krato\ssa_project\users\forms.py", line 22, in save
    user.save()
    ~~~~~~~~~^^
  File "C:\Users\krato\AppData\Roaming\Python\Python313\site-packages\django\contrib\auth\base_user.py", line 62, in save
    super().save(*args, **kwargs)
    ~~~~~~~~~~~~^^^^^^^^^^^^^^^^^
  File "C:\Users\krato\AppData\Roaming\Python\Python313\site-packages\django\db\models\base.py", line 891, in save
    self.save_base(
    ~~~~~~~~~~~~~~^
        using=using,
        ^^^^^^^^^^^^
    ...<2 lines>...
        update_fields=update_fields,
        ^^^^^^^^^^^^^^^^^^^^^^^^^^^^
    )
    ^
  File "C:\Users\krato\AppData\Roaming\Python\Python313\site-packages\django\db\models\base.py", line 1012, in save_base
    post_save.send(
    ~~~~~~~~~~~~~~^
        sender=origin,
        ^^^^^^^^^^^^^^
    ...<4 lines>...
        using=using,
        ^^^^^^^^^^^^
    )
    ^
  File "C:\Users\krato\AppData\Roaming\Python\Python313\site-packages\django\dispatch\dispatcher.py", line 189, in send
    response = receiver(signal=self, sender=sender, **named)
  File "C:\Users\krato\ssa_project\users\models.py", line 10, in create_user_profile
    Profile.objects.get_or_create(user=instance)  # Safely create the profile without duplicating
    ~~~~~~~~~~~~~~~~~~~~~~~~~~~~~^^^^^^^^^^^^^^^
  File "C:\Users\krato\AppData\Roaming\Python\Python313\site-packages\django\db\models\manager.py", line 87, in manager_method
    return getattr(self.get_queryset(), name)(*args, **kwargs)
           ~~~~~~~~~~~~~~~~~~~~~~~~~~~~~~~~~~^^^^^^^^^^^^^^^^^
  File "C:\Users\krato\AppData\Roaming\Python\Python313\site-packages\django\db\models\query.py", line 955, in get_or_create
    return self.create(**params), True
           ~~~~~~~~~~~^^^^^^^^^^
  File "C:\Users\krato\AppData\Roaming\Python\Python313\site-packages\django\db\models\query.py", line 679, in create
    obj.save(force_insert=True, using=self.db)
    ~~~~~~~~^^^^^^^^^^^^^^^^^^^^^^^^^^^^^^^^^^
  File "C:\Users\krato\ssa_project\users\models.py", line 36, in save
    self.clean()
    ~~~~~~~~~~^^
  File "C:\Users\krato\ssa_project\users\models.py", line 33, in clean
    validate_unique_nickname(self.nickname, instance=self)
    ~~~~~~~~~~~~~~~~~~~~~~~~^^^^^^^^^^^^^^^^^^^^^^^^^^^^^^
  File "C:\Users\krato\ssa_project\users\models.py", line 21, in validate_unique_nickname
    raise ValidationError(f"Nickname '{nickname}' is already taken.")
django.core.exceptions.ValidationError: ["Nickname '' is already taken."]
"POST /users/register/ HTTP/1.1" 500 128758
Internal Server Error: /users/register/
Traceback (most recent call last):
  File "C:\Users\krato\AppData\Roaming\Python\Python313\site-packages\django\db\models\query.py", line 948, in get_or_create
    return self.get(**kwargs), False
           ~~~~~~~~^^^^^^^^^^
  File "C:\Users\krato\AppData\Roaming\Python\Python313\site-packages\django\db\models\query.py", line 649, in get
    raise self.model.DoesNotExist(
        "%s matching query does not exist." % self.model._meta.object_name
    )
users.models.Profile.DoesNotExist: Profile matching query does not exist.

During handling of the above exception, another exception occurred:

Traceback (most recent call last):
  File "C:\Users\krato\AppData\Roaming\Python\Python313\site-packages\django\core\handlers\exception.py", line 55, in inner
    response = get_response(request)
  File "C:\Users\krato\AppData\Roaming\Python\Python313\site-packages\django\core\handlers\base.py", line 197, in _get_response
    response = wrapped_callback(request, *callback_args, **callback_kwargs)
  File "C:\Users\krato\ssa_project\users\views.py", line 16, in register
    form.save()
    ~~~~~~~~~^^
  File "C:\Users\krato\ssa_project\users\forms.py", line 22, in save
    user.save()
    ~~~~~~~~~^^
  File "C:\Users\krato\AppData\Roaming\Python\Python313\site-packages\django\contrib\auth\base_user.py", line 62, in save
    super().save(*args, **kwargs)
    ~~~~~~~~~~~~^^^^^^^^^^^^^^^^^
  File "C:\Users\krato\AppData\Roaming\Python\Python313\site-packages\django\db\models\base.py", line 891, in save
    self.save_base(
    ~~~~~~~~~~~~~~^
        using=using,
        ^^^^^^^^^^^^
    ...<2 lines>...
        update_fields=update_fields,
        ^^^^^^^^^^^^^^^^^^^^^^^^^^^^
    )
    ^
  File "C:\Users\krato\AppData\Roaming\Python\Python313\site-packages\django\db\models\base.py", line 1012, in save_base
    post_save.send(
    ~~~~~~~~~~~~~~^
        sender=origin,
        ^^^^^^^^^^^^^^
    ...<4 lines>...
        using=using,
        ^^^^^^^^^^^^
    )
    ^
  File "C:\Users\krato\AppData\Roaming\Python\Python313\site-packages\django\dispatch\dispatcher.py", line 189, in send
    response = receiver(signal=self, sender=sender, **named)
  File "C:\Users\krato\ssa_project\users\models.py", line 10, in create_user_profile
    Profile.objects.get_or_create(user=instance)  # Safely create the profile without duplicating
    ~~~~~~~~~~~~~~~~~~~~~~~~~~~~~^^^^^^^^^^^^^^^
  File "C:\Users\krato\AppData\Roaming\Python\Python313\site-packages\django\db\models\manager.py", line 87, in manager_method
    return getattr(self.get_queryset(), name)(*args, **kwargs)
           ~~~~~~~~~~~~~~~~~~~~~~~~~~~~~~~~~~^^^^^^^^^^^^^^^^^
  File "C:\Users\krato\AppData\Roaming\Python\Python313\site-packages\django\db\models\query.py", line 955, in get_or_create
    return self.create(**params), True
           ~~~~~~~~~~~^^^^^^^^^^
  File "C:\Users\krato\AppData\Roaming\Python\Python313\site-packages\django\db\models\query.py", line 679, in create
    obj.save(force_insert=True, using=self.db)
    ~~~~~~~~^^^^^^^^^^^^^^^^^^^^^^^^^^^^^^^^^^
  File "C:\Users\krato\ssa_project\users\models.py", line 36, in save
    self.clean()
    ~~~~~~~~~~^^
  File "C:\Users\krato\ssa_project\users\models.py", line 33, in clean
    validate_unique_nickname(self.nickname, instance=self)
    ~~~~~~~~~~~~~~~~~~~~~~~~^^^^^^^^^^^^^^^^^^^^^^^^^^^^^^
  File "C:\Users\krato\ssa_project\users\models.py", line 21, in validate_unique_nickname
    raise ValidationError(f"Nickname '{nickname}' is already taken.")
django.core.exceptions.ValidationError: ["Nickname '' is already taken."]
"POST /users/register/ HTTP/1.1" 500 128617
Internal Server Error: /users/
Traceback (most recent call last):
  File "C:\Users\krato\AppData\Roaming\Python\Python313\site-packages\django\core\handlers\exception.py", line 55, in inner
    response = get_response(request)
  File "C:\Users\krato\AppData\Roaming\Python\Python313\site-packages\django\core\handlers\base.py", line 197, in _get_response
    response = wrapped_callback(request, *callback_args, **callback_kwargs)
  File "C:\Users\krato\AppData\Roaming\Python\Python313\site-packages\django\contrib\auth\decorators.py", line 60, in _view_wrapper
    return view_func(request, *args, **kwargs)
  File "C:\Users\krato\ssa_project\users\views.py", line 98, in user
    'balance': profile.balance,
               ^^^^^^^^^^^^^^^
AttributeError: 'Profile' object has no attribute 'balance'
"GET /users/ HTTP/1.1" 500 69711
Internal Server Error: /users/
Traceback (most recent call last):
  File "C:\Users\krato\AppData\Roaming\Python\Python313\site-packages\django\core\handlers\exception.py", line 55, in inner
    response = get_response(request)
  File "C:\Users\krato\AppData\Roaming\Python\Python313\site-packages\django\core\handlers\base.py", line 197, in _get_response
    response = wrapped_callback(request, *callback_args, **callback_kwargs)
  File "C:\Users\krato\AppData\Roaming\Python\Python313\site-packages\django\contrib\auth\decorators.py", line 60, in _view_wrapper
    return view_func(request, *args, **kwargs)
  File "C:\Users\krato\ssa_project\users\views.py", line 94, in user
    profile = request.user.profile
              ^^^^^^^^^^^^^^^^^^^^
  File "C:\Users\krato\AppData\Roaming\Python\Python313\site-packages\django\utils\functional.py", line 253, in inner
    return func(_wrapped, *args)
  File "C:\Users\krato\AppData\Roaming\Python\Python313\site-packages\django\db\models\fields\related_descriptors.py", line 531, in __get__
    raise self.RelatedObjectDoesNotExist(
    ...<2 lines>...
    )
django.contrib.auth.models.User.profile.RelatedObjectDoesNotExist: User has no profile.
"GET /users/ HTTP/1.1" 500 78312
Internal Server Error: /users/register/
Traceback (most recent call last):
  File "C:\Users\krato\AppData\Roaming\Python\Python313\site-packages\django\db\models\query.py", line 948, in get_or_create
    return self.get(**kwargs), False
           ~~~~~~~~^^^^^^^^^^
  File "C:\Users\krato\AppData\Roaming\Python\Python313\site-packages\django\db\models\query.py", line 649, in get
    raise self.model.DoesNotExist(
        "%s matching query does not exist." % self.model._meta.object_name
    )
users.models.Profile.DoesNotExist: Profile matching query does not exist.

During handling of the above exception, another exception occurred:

Traceback (most recent call last):
  File "C:\Users\krato\AppData\Roaming\Python\Python313\site-packages\django\core\handlers\exception.py", line 55, in inner
    response = get_response(request)
  File "C:\Users\krato\AppData\Roaming\Python\Python313\site-packages\django\core\handlers\base.py", line 197, in _get_response
    response = wrapped_callback(request, *callback_args, **callback_kwargs)
  File "C:\Users\krato\ssa_project\users\views.py", line 16, in register
    form.save()
    ~~~~~~~~~^^
  File "C:\Users\krato\ssa_project\users\forms.py", line 22, in save
    user.save()
    ~~~~~~~~~^^
  File "C:\Users\krato\AppData\Roaming\Python\Python313\site-packages\django\contrib\auth\base_user.py", line 62, in save
    super().save(*args, **kwargs)
    ~~~~~~~~~~~~^^^^^^^^^^^^^^^^^
  File "C:\Users\krato\AppData\Roaming\Python\Python313\site-packages\django\db\models\base.py", line 891, in save
    self.save_base(
    ~~~~~~~~~~~~~~^
        using=using,
        ^^^^^^^^^^^^
    ...<2 lines>...
        update_fields=update_fields,
        ^^^^^^^^^^^^^^^^^^^^^^^^^^^^
    )
    ^
  File "C:\Users\krato\AppData\Roaming\Python\Python313\site-packages\django\db\models\base.py", line 1012, in save_base
    post_save.send(
    ~~~~~~~~~~~~~~^
        sender=origin,
        ^^^^^^^^^^^^^^
    ...<4 lines>...
        using=using,
        ^^^^^^^^^^^^
    )
    ^
  File "C:\Users\krato\AppData\Roaming\Python\Python313\site-packages\django\dispatch\dispatcher.py", line 189, in send
    response = receiver(signal=self, sender=sender, **named)
  File "C:\Users\krato\ssa_project\users\models.py", line 10, in create_user_profile
    Profile.objects.get_or_create(user=instance)  # Safely create the profile without duplicating
    ~~~~~~~~~~~~~~~~~~~~~~~~~~~~~^^^^^^^^^^^^^^^
  File "C:\Users\krato\AppData\Roaming\Python\Python313\site-packages\django\db\models\manager.py", line 87, in manager_method
    return getattr(self.get_queryset(), name)(*args, **kwargs)
           ~~~~~~~~~~~~~~~~~~~~~~~~~~~~~~~~~~^^^^^^^^^^^^^^^^^
  File "C:\Users\krato\AppData\Roaming\Python\Python313\site-packages\django\db\models\query.py", line 955, in get_or_create
    return self.create(**params), True
           ~~~~~~~~~~~^^^^^^^^^^
  File "C:\Users\krato\AppData\Roaming\Python\Python313\site-packages\django\db\models\query.py", line 679, in create
    obj.save(force_insert=True, using=self.db)
    ~~~~~~~~^^^^^^^^^^^^^^^^^^^^^^^^^^^^^^^^^^
  File "C:\Users\krato\ssa_project\users\models.py", line 39, in save
    self.clean()
    ~~~~~~~~~~^^
  File "C:\Users\krato\ssa_project\users\models.py", line 36, in clean
    validate_unique_nickname(self.nickname, instance=self)
    ~~~~~~~~~~~~~~~~~~~~~~~~^^^^^^^^^^^^^^^^^^^^^^^^^^^^^^
  File "C:\Users\krato\ssa_project\users\models.py", line 21, in validate_unique_nickname
    raise ValidationError(f"Nickname '{nickname}' is already taken.")
django.core.exceptions.ValidationError: ["Nickname '' is already taken."]
"POST /users/register/ HTTP/1.1" 500 128701
